Workbook
Name scenario: Inputs!$C$2
Name cohort_size: Inputs!$F$8
Name cohort_size_ng: Inputs!$J$8
Name mix_gig: Inputs!$F$9
Name mix_gig_ng: Inputs!$J$9
Name disc_rate: Inputs!$F$10
Name disc_rate_ng: Inputs!$J$10
Name usd_inr: Inputs!$F$11
Name usd_inr_ng: Inputs!$J$11
Name ret_m1: Inputs!$F$13
Name ret_m1_ng: Inputs!$J$13
Name ret_m3: Inputs!$F$14
Name ret_m3_ng: Inputs!$J$14
Name ret_m6: Inputs!$F$15
Name ret_m6_ng: Inputs!$J$15
Name ret_m12: Inputs!$F$16
Name ret_m12_ng: Inputs!$J$16
Name ret_m24: Inputs!$F$17
Name ret_m24_ng: Inputs!$J$17
Name churn_late: Inputs!$F$18
Name churn_late_ng: Inputs!$J$18
Name daily_amount: Inputs!$F$20
Name daily_amount_ng: Inputs!$J$20
Name amount_growth: Inputs!$F$21
Name amount_growth_ng: Inputs!$J$21
Name debits_scheduled: Inputs!$F$22
Name debits_scheduled_ng: Inputs!$J$22
Name debits_success: Inputs!$F$23
Name debits_success_ng: Inputs!$J$23
Name withdraw_rate: Inputs!$F$24
Name withdraw_rate_ng: Inputs!$J$24
Name leaver_withdraw: Inputs!$F$25
Name leaver_withdraw_ng: Inputs!$J$25
Name dormant_withdraw: Inputs!$F$26
Name dormant_withdraw_ng: Inputs!$J$26
Name fund_yield: Inputs!$F$27
Name fund_yield_ng: Inputs!$J$27
Name fd_share: Inputs!$F$28
Name fd_share_ng: Inputs!$J$28
Name fd_start: Inputs!$F$29
Name fd_start_ng: Inputs!$J$29
Name trail_liquid: Inputs!$F$31
Name trail_liquid_ng: Inputs!$J$31
Name fd_fee: Inputs!$F$32
Name fd_fee_ng: Inputs!$J$32
Name mf_incentive: Inputs!$F$33
Name mf_incentive_ng: Inputs!$J$33
Name first_time_share: Inputs!$F$34
Name first_time_share_ng: Inputs!$J$34
Name loan_start: Inputs!$F$36
Name loan_start_ng: Inputs!$J$36
Name loan_eligible: Inputs!$F$37
Name loan_eligible_ng: Inputs!$J$37
Name loan_apply: Inputs!$F$38
Name loan_apply_ng: Inputs!$J$38
Name loan_approval: Inputs!$F$39
Name loan_approval_ng: Inputs!$J$39
Name loan_ticket: Inputs!$F$40
Name loan_ticket_ng: Inputs!$J$40
Name loan_stepup: Inputs!$F$41

Sheet Inputs
A1: Inputs: every assumption, one row each
A2: Scenario (1 = bear, 2 = base, 3 = bull) | C2: 2 | D2: =CHOOSE(scenario,"Bear","Base","Bull")
A3: Blue = typed input. Black = formula. Green = link to another sheet. Yellow row = waiting on research, or a claim the pilot must prove. Every model cell uses the LIVE column, which follows the scenario switch in C2. Channel inputs sit on 'Funnel & CAC'; yearly growth inputs on 'Path to $100M'.
A5: id | B5: Assumption | C5: Bear | D5: Base | E5: Bull | F5: LIVE (gig) | G5: Non-gig bear | H5: Non-gig base | I5: Non-gig bull | J5: LIVE (non-gig) | K5: Unit | L5: Population | M5: Basis | N5: Non-gig basis | O5: Source | P5: As of | Q5: Notes
A6: Savings-first model (non-gig columns blank = same as gig)
B7: General
A8: cohort_size | B8: Activated savers in one monthly cohort | C8: 1000 | D8: 1000 | E8: 1000 | F8: =CHOOSE(scenario,C8,D8,E8) | J8: =IF(H8="",F8,CHOOSE(scenario,G8,H8,I8)) | K8: savers | L8: one monthly cohort | M8: definition | P8: 2026-09-30 | Q8: Activated = first successful auto-debit
A9: mix_gig | B9: Share of activated savers who are gig workers | C9: 0.5 | D9: 0.5 | E9: 0.5 | F9: =CHOOSE(scenario,C9,D9,E9) | J9: =IF(H9="",F9,CHOOSE(scenario,G9,H9,I9)) | K9: share | L9: each monthly cohort | M9: founder decision (2026-09-30) | P9: 2026-09-30 | Q9: Half gig (app delivery and ride), half non-gig (shopkeepers, self-employed trades, workers outside the apps, small business owners), from day one
A10: disc_rate | B10: Discount rate for LTV | C10: 0.2 | D10: 0.2 | E10: 0.2 | F10: =CHOOSE(scenario,C10,D10,E10) | J10: =IF(H10="",F10,CHOOSE(scenario,G10,H10,I10)) | K10: per year | L10: all cash flows | M10: assumption | P10: 2026-09-30 | Q10: Stated on every LTV figure
A11: usd_inr | B11: Rupees per US dollar | C11: 96.1 | D11: 96.1 | E11: 96.1 | F11: =CHOOSE(scenario,C11,D11,E11) | J11: =IF(H11="",F11,CHOOSE(scenario,G11,H11,I11)) | K11: INR per USD | L11: conversion for $ figures | M11: market rate | O11: OWN-01 | P11: 2026-09-30 | Q11: Spot rate on 30 Sep 2026
B12: Retention
A13: ret_m1 | B13: Share of activated savers still saving in month 1 | C13: 0.6 | D13: 0.7 | E13: 0.8 | F13: =CHOOSE(scenario,C13,D13,E13) | G13: 0.7 | H13: 0.72 | I13: 0.8 | J13: =IF(H13="",F13,CHOOSE(scenario,G13,H13,I13)) | K13: share | L13: per activated saver | M13: founder view (2026-09-30) | N13: benchmark proxies + judgement (no shopkeeper-specific data) | O13: INC-01 | P13: 2026-09-30 | Q13: Shape interpolated to meet the founder's 20 at 1 year / 10 at 2 years
A14: ret_m3 | B14: Still saving in month 3 | C14: 0.38 | D14: 0.48 | E14: 0.6 | F14: =CHOOSE(scenario,C14,D14,E14) | G14: 0.48 | H14: 0.53 | I14: 0.65 | J14: =IF(H14="",F14,CHOOSE(scenario,G14,H14,I14)) | K14: share | L14: per activated saver | M14: founder view (2026-09-30) | N14: benchmark proxies + judgement (no shopkeeper-specific data) | O14: INC-01 | P14: 2026-09-30
A15: ret_m6 | B15: Still saving in month 6 | C15: 0.24 | D15: 0.33 | E15: 0.45 | F15: =CHOOSE(scenario,C15,D15,E15) | G15: 0.33 | H15: 0.4 | I15: 0.53 | J15: =IF(H15="",F15,CHOOSE(scenario,G15,H15,I15)) | K15: share | L15: per activated saver | M15: founder view (2026-09-30) | N15: benchmark proxies + judgement (no shopkeeper-specific data); SBI daily Rs 250 SIP lost 35.6% of FY26 registrations within the year | O15: INC-01 | P15: 2026-09-30
A16: ret_m12 | B16: Still saving in month 12 | C16: 0.13 | D16: 0.2 | E16: 0.32 | F16: =CHOOSE(scenario,C16,D16,E16) | G16: 0.2 | H16: 0.25 | I16: 0.4 | J16: =IF(H16="",F16,CHOOSE(scenario,G16,H16,I16)) | K16: share | L16: per activated saver | M16: founder view (2026-09-30) | N16: benchmark proxies + judgement (no shopkeeper-specific data); bear = gig base | O16: INC-01 | P16: 2026-09-30 | Q16: Founder: of 100 who start, about 20 still saving after a year. Rider tenure averages about 13 months [INC-01].
A17: ret_m24 | B17: Still saving in month 24 | C17: 0.06 | D17: 0.1 | E17: 0.2 | F17: =CHOOSE(scenario,C17,D17,E17) | G17: 0.1 | H17: 0.15 | I17: 0.25 | J17: =IF(H17="",F17,CHOOSE(scenario,G17,H17,I17)) | K17: share | L17: per activated saver | M17: founder view (2026-09-30) | N17: benchmark proxies + judgement (no shopkeeper-specific data) | O17: INC-01 | P17: 2026-09-30 | Q17: Founder: about 10 of 100 still saving after two years.
A18: churn_late | B18: Monthly churn after month 24 | C18: 0.03 | D18: 0.02 | E18: 0.012 | F18: =CHOOSE(scenario,C18,D18,E18) | G18: 0.02 | H18: 0.015 | I18: 0.01 | J18: =IF(H18="",F18,CHOOSE(scenario,G18,H18,I18)) | K18: share per month | L18: active savers after month 24 | M18: assumption | N18: assumption | P18: 2026-09-30
B19: Saving
A20: daily_amount | B20: Amount per successful debit | C20: 25 | D20: 40 | E20: 60 | F20: =CHOOSE(scenario,C20,D20,E20) | G20: 30 | H20: 50 | I20: 100 | J20: =IF(H20="",F20,CHOOSE(scenario,G20,H20,I20)) | K20: INR per debit | L20: active savers year 1 | M20: assumption, sized against income | N20: benchmark: vendors save 2.2x drivers (Kenya RCT); Bachatt Rs 100-200/day and pigmy Rs 100+/day tickets; mix includes low earners. Income is NOT a clean comparison: PLFS self-employed earnings (Rs 23k urban) may be before business costs, gig Rs 18.8k is net | O20: INC-01, BAC-04, REG-043 | P20: 2026-09-30 | Q20: Daily design chosen by founder (2026-09-30). Rs 40 x 20 debits = Rs 800/month, about 4% of a full-time rider's net Rs 18,761. CONSTRAINT: daily fund saving needs at least Rs 100 a debit [REG-043]; Rs 10-99 a day works only with digital gold (gold_on) or by accumulating in the worker's own bank.
A21: amount_growth | B21: Yearly growth in amount per debit | C21: 0.05 | D21: 0.1 | E21: 0.15 | F21: =CHOOSE(scenario,C21,D21,E21) | J21: =IF(H21="",F21,CHOOSE(scenario,G21,H21,I21)) | K21: per year | L21: active savers | M21: assumption | P21: 2026-09-30
A22: debits_scheduled | B22: Debits scheduled per month | C22: 30 | D22: 30 | E22: 30 | F22: =CHOOSE(scenario,C22,D22,E22) | J22: =IF(H22="",F22,CHOOSE(scenario,G22,H22,I22)) | K22: debits per month | L22: active savers | M22: product design | P22: 2026-09-30 | Q22: Daily plan; set 4 for a weekly plan
A23: debits_success | B23: Successful debits per month | C23: 15 | D23: 20 | E23: 24 | F23: =CHOOSE(scenario,C23,D23,E23) | G23: 16 | H23: 22 | I23: 25 | J23: =IF(H23="",F23,CHOOSE(scenario,G23,H23,I23)) | K23: debits per month | L23: active savers | M23: assumption | N23: assumption: daily cash flow bounces fewer debits | O23: REG-047 | P23: 2026-09-30 | Q23: Daily plan. Debits may run only outside peak hours; one attempt plus three retries.
A24: withdraw_rate | B24: Share of balance withdrawn per month by active savers | C24: 0.15 | D24: 0.1 | E24: 0.06 | F24: =CHOOSE(scenario,C24,D24,E24) | J24: =IF(H24="",F24,CHOOSE(scenario,G24,H24,I24)) | K24: share per month | L24: active savers | M24: assumption | P24: 2026-09-30
A25: leaver_withdraw | B25: Share of balance withdrawn in the month a saver stops | C25: 0.8 | D25: 0.6 | E25: 0.4 | F25: =CHOOSE(scenario,C25,D25,E25) | J25: =IF(H25="",F25,CHOOSE(scenario,G25,H25,I25)) | K25: share | L25: savers who stop | M25: assumption | P25: 2026-09-30
A26: dormant_withdraw | B26: Share of dormant balance withdrawn per month | C26: 0.08 | D26: 0.05 | E26: 0.03 | F26: =CHOOSE(scenario,C26,D26,E26) | J26: =IF(H26="",F26,CHOOSE(scenario,G26,H26,I26)) | K26: share per month | L26: stopped savers' remaining balance | M26: assumption | P26: 2026-09-30
A27: fund_yield | B27: Liquid fund / FD yield to saver | C27: 0.05 | D27: 0.055 | E27: 0.06 | F27: =CHOOSE(scenario,C27,D27,E27) | J27: =IF(H27="",F27,CHOOSE(scenario,G27,H27,I27)) | K27: per year | L27: savings balance | M27: benchmark | O27: OWN-02 | P27: 2026 | Q27: Liquid funds 5-6% a year with repo at 5.25%; FDs at small banks pay somewhat more
A28: fd_share | B28: Share of savings balance held in bank FDs | C28: 0.2 | D28: 0.3 | E28: 0.4 | F28: =CHOOSE(scenario,C28,D28,E28) | J28: =IF(H28="",F28,CHOOSE(scenario,G28,H28,I28)) | K28: share | L28: savings balance from FD start month | M28: assumption | P28: 2026-09-30 | Q28: Goal money
A29: fd_start | B29: Month FDs start | C29: 6 | D29: 6 | E29: 6 | F29: =CHOOSE(scenario,C29,D29,E29) | J29: =IF(H29="",F29,CHOOSE(scenario,G29,H29,I29)) | K29: month | L29: cohort age | M29: product design | P29: 2026-09-30
B30: Revenue: savings
A31: trail_liquid | B31: Distributor trail on liquid-fund balance | C31: 0.0005 | D31: 0.0008 | E31: 0.0012 | F31: =CHOOSE(scenario,C31,D31,E31) | J31: =IF(H31="",F31,CHOOSE(scenario,G31,H31,I31)) | K31: per year | L31: liquid-fund balance (regular plan) | M31: benchmark: regular minus direct TER gap (an upper bound on trail) | O31: BM-01 | P31: 2026-08-31 | Q31: ICICI Pru Liquid 0.25% vs 0.17%; SBI Liquid 0.29% vs 0.17%. About Rs 4 a year on a Rs 5,000 balance.
A32: fd_fee | B32: Distribution fee on FD balance | C32: 0.0025 | D32: 0.005 | E32: 0.01 | F32: =CHOOSE(scenario,C32,D32,E32) | J32: =IF(H32="",F32,CHOOSE(scenario,G32,H32,I32)) | K32: per year | L32: FD balance | M32: benchmark, UNVERIFIED (anecdotal) | O32: BM-03 | P32: 2025-02 | Q32: Stable Money about 1% (anonymous source); Altcase 0.4%. Banks publish no rate. Modelled as a yearly % of FD balance, assuming 1-year FDs rebooked through us.
A33: mf_incentive | B33: One-time incentive per first-time MF investor | C33: 0 | D33: 0 | E33: 0 | F33: =CHOOSE(scenario,C33,D33,E33) | J33: =IF(H33="",F33,CHOOSE(scenario,G33,H33,I33)) | K33: INR per investor | L33: first-time investors starting a small SIP | M33: regulation: SEBI Choti SIP (not available to this design) | O33: REG-032, REG-033 | P33: 2025-08-11 | Q33: Rs 500 per new-to-MF investor, paid after 24 months, monthly Rs 250 equity SIP only. Forfeited if the investor holds ANY other SIP or lumpsum, and our liquid-fund saving comes first. So Rs 0 here.
A34: first_time_share | B34: Share of savers who are first-time MF investors | C34: 0.9 | D34: 0.9 | E34: 0.9 | F34: =CHOOSE(scenario,C34,D34,E34) | J34: =IF(H34="",F34,CHOOSE(scenario,G34,H34,I34)) | K34: share | L34: activated savers | M34: benchmark: company claim | O34: JAR-07 | P34: 2025-09-18 | Q34: Jar says more than 95% of its users save formally for the first time (method undisclosed).
B35: Revenue: loans
A36: loan_start | B36: Month a saver can first get a loan offer | C36: 6 | D36: 4 | E36: 3 | F36: =CHOOSE(scenario,C36,D36,E36) | J36: =IF(H36="",F36,CHOOSE(scenario,G36,H36,I36)) | K36: month | L36: cohort age | M36: product design | P36: 2026-09-30 | Q36: After a saving streak
A37: loan_eligible | B37: Share of active savers eligible for a loan offer | C37: 0.3 | D37: 0.5 | E37: 0.65 | F37: =CHOOSE(scenario,C37,D37,E37) | J37: =IF(H37="",F37,CHOOSE(scenario,G37,H37,I37)) | K37: share | L37: active savers from loan start | M37: assumption; cross-checked against the share who ever borrow | O37: LEND-04, CMP-07, CMP-05 | P37: 2026-09-30 | Q37: Benchmarks for share who ever borrow: 8% of Moneyview registered users, 11% of GCash lifetime users, 34% of eligible M-Shwari users.
A38: loan_apply | B38: Monthly application rate among eligible never-borrowed savers | C38: 0.02 | D38: 0.04 | E38: 0.06 | F38: =CHOOSE(scenario,C38,D38,E38) | J38: =IF(H38="",F38,CHOOSE(scenario,G38,H38,I38)) | K38: share per month | L38: eligible active savers who never borrowed | M38: assumption | P38: 2026-09-30
A39: loan_approval | B39: Partner approval rate for our applicants | C39: 0.4 | D39: 0.6 | E39: 0.75 | F39: =CHOOSE(scenario,C39,D39,E39) | G39: 0.35 | H39: 0.55 | I39: 0.7 | J39: =IF(H39="",F39,CHOOSE(scenario,G39,H39,I39)) | K39: share | L39: applications from eligible savers | M39: assumption (claim 2: pilot must prove) | N39: assumption: more new-to-credit, no payslip or platform data | O39: EVD-02, EVD-03 | P39: 2026-09-30 | Q39: No evidence yet that savings behaviour predicts repayment in this segment. Platform-app data does predict creditworthiness (RappiCard, EVD-02).
A40: loan_ticket | B40: Unsecured loan size (loan 5 onward) | C40: 10000 | D40: 15000 | E40: 20000 | F40: =CHOOSE(scenario,C40,D40,E40) | J40: =IF(H40="",F40,CHOOSE(scenario,G40,H40,I40)) | K40: INR | L40: unsecured loans on the ladder (loan 5+) | M40: assumption | P40: 2026-09-30 | Q40: Ladder (founder, 2 Oct 2026): loans 1-2 secured against savings, 3-4 part secured, 5+ unsecured at this size. Bueno first loans Rs 10k-25k.
A41: loan_stepup | B41: Repeat loan size as a multiple of the first | C41: 1 | D41: 1.2 | E41: 1.4 | F41: =CHOOSE(scenario,C41,D41,E41) | J41: =IF(H41="",F41,CHOOSE(scenario,G41,H41,I41)) | K41: multiple | L41: repeat loans | M41: assumption | P41: 2026-09-30 | Q41: Not used by the ladder (kept for reference).
...

Sheet Funnel & CAC
A1: Funnel & CAC: fully loaded cost per ACTIVATED saver (first successful auto-debit), by channel
A2: CAC per activated saver = cost per install × scenario multiplier ÷ (install→activated) + KYC cost ÷ (KYC→activated) + mandate cost ÷ (mandate→first debit) + reward + referral bonus + partner fee.
A4: Channel | B4: Share of its segment | C4: Cost per install (₹) | D4: Install → KYC | E4: KYC → mandate | F4: Mandate → first debit | G4: KYC cost per KYC (₹) | H4: Mandate cost per mandate (₹) | I4: Joining reward (₹) | J4: Referral bonus (₹) | K4: Partner fee (₹) | L4: Install → activated | M4: Acquisition per activated (₹) | N4: KYC per activated (₹) | O4: Mandate per activated (₹) | P4: Rewards + referral + partner (₹) | Q4: CAC per activated saver (₹) | R4: Basis | S4: Notes | T4: Install weight (share of all savers ÷ install→activated)
A5: Gig · Save at source (platform / fleet payouts) | B5: 0.3 | C5: 60 | D5: 0.7 | E5: 0.85 | F5: 0.9 | G5: 40 | H5: 5 | I5: 0 | J5: 0 | K5: 50 | L5: =D5*E5*F5 | M5: =C5*cac_mult/L5 | N5: =G5/(E5*F5) | O5: =H5/F5 | P5: =I5+J5+K5 | Q5: =M5+N5+O5+P5 | R5: assumption: no savings-app CAC found [BM-04, BM-05]; Bueno cost per applicant under Rs 150 is the founder anchor | S5: Field staff at hubs co-branded with a platform; partner fee assumed | KYC Rs 40 = Aadhaar e-KYC Rs 3 (UIDAI) + vendor + KRA upload Rs 30 + CKYC [REG-068, REG-045, REG-069]; mandate Rs 5 (list Rs 7.5) [REG-050] | T5: =B5*mix_gig/L5
A6: Gig · Rider hubs and dark stores (field agents) | B6: 0.3 | C6: 50 | D6: 0.6 | E6: 0.7 | F6: 0.85 | G6: 40 | H6: 5 | I6: 0 | J6: 0 | K6: 0 | L6: =D6*E6*F6 | M6: =C6*cac_mult/L6 | N6: =G6/(E6*F6) | O6: =H6/F6 | P6: =I6+J6+K6 | Q6: =M6+N6+O6+P6 | R6: assumption: no savings-app CAC found [BM-04, BM-05]; Bueno cost per applicant under Rs 150 is the founder anchor | S6: Rs 25k/month agent / 25 days / 20 installs a day = Rs 50 | KYC Rs 40 = Aadhaar e-KYC Rs 3 (UIDAI) + vendor + KRA upload Rs 30 + CKYC [REG-068, REG-045, REG-069]; mandate Rs 5 (list Rs 7.5) [REG-050] | T6: =B6*mix_gig/L6
A7: Gig · Savings-buddy referrals | B7: 0.2 | C7: 0 | D7: 0.5 | E7: 0.7 | F7: 0.85 | G7: 40 | H7: 5 | I7: 0 | J7: 0 | K7: 0 | L7: =D7*E7*F7 | M7: =C7*cac_mult/L7 | N7: =G7/(E7*F7) | O7: =H7/F7 | P7: =I7+J7+K7 | Q7: =M7+N7+O7+P7 | R7: assumption: no savings-app CAC found [BM-04, BM-05]; Bueno cost per applicant under Rs 150 is the founder anchor | S7: Non-cash: shared goals and streaks with a friend. No cash bonus, because distributors may not reward fund investment [REG-082]. No pooling, because that would be a chit [REG-080]. | KYC Rs 40 = Aadhaar e-KYC Rs 3 (UIDAI) + vendor + KRA upload Rs 30 + CKYC [REG-068, REG-045, REG-069]; mandate Rs 5 (list Rs 7.5) [REG-050] | T7: =B7*mix_gig/L7
A8: Gig · Local-language creators and WhatsApp groups | B8: 0.1 | C8: 40 | D8: 0.4 | E8: 0.6 | F8: 0.8 | G8: 40 | H8: 5 | I8: 0 | J8: 0 | K8: 0 | L8: =D8*E8*F8 | M8: =C8*cac_mult/L8 | N8: =G8/(E8*F8) | O8: =H8/F8 | P8: =I8+J8+K8 | Q8: =M8+N8+O8+P8 | R8: assumption: no savings-app CAC found [BM-04, BM-05]; Bueno cost per applicant under Rs 150 is the founder anchor | S8: KYC Rs 40 = Aadhaar e-KYC Rs 3 (UIDAI) + vendor + KRA upload Rs 30 + CKYC [REG-068, REG-045, REG-069]; mandate Rs 5 (list Rs 7.5) [REG-050] | T8: =B8*mix_gig/L8
A9: Gig · Paid ads (benchmark only) | B9: 0.1 | C9: 80 | D9: 0.3 | E9: 0.55 | F9: 0.75 | G9: 40 | H9: 5 | I9: 0 | J9: 0 | K9: 0 | L9: =D9*E9*F9 | M9: =C9*cac_mult/L9 | N9: =G9/(E9*F9) | O9: =H9/F9 | P9: =I9+J9+K9 | Q9: =M9+N9+O9+P9 | R9: assumption: no savings-app CAC found [BM-04, BM-05]; Bueno cost per applicant under Rs 150 is the founder anchor | S9: KYC Rs 40 = Aadhaar e-KYC Rs 3 (UIDAI) + vendor + KRA upload Rs 30 + CKYC [REG-068, REG-045, REG-069]; mandate Rs 5 (list Rs 7.5) [REG-050] | T9: =B9*mix_gig/L9
A10: Non-gig · Field agents in markets | B10: 0.35 | C10: 50 | D10: 0.55 | E10: 0.7 | F10: 0.85 | G10: 40 | H10: 5 | I10: 0 | J10: 0 | K10: 0 | L10: =D10*E10*F10 | M10: =C10*cac_mult_ng/L10 | N10: =G10/(E10*F10) | O10: =H10/F10 | P10: =I10+J10+K10 | Q10: =M10+N10+O10+P10 | R10: assumption: merchant onboarding cost not disclosed by any payments firm [NG-043]; PhonePe has about 358 merchant devices per field staff (derived) [NG-029] | S10: Agents walk market streets and sign shops up. Staff who explain funds need NISM certification; no sign-up gifts for fund investing [OWN-05, REG-082] | T10: =B10*(1-mix_gig)/L10
A11: Non-gig · Supplier and distributor networks | B11: 0.25 | C11: 30 | D11: 0.5 | E11: 0.7 | F11: 0.85 | G11: 40 | H11: 5 | I11: 0 | J11: 0 | K11: 50 | L11: =D11*E11*F11 | M11: =C11*cac_mult_ng/L11 | N11: =G11/(E11*F11) | O11: =H11/F11 | P11: =I11+J11+K11 | Q11: =M11+N11+O11+P11 | R11: assumption: supplier-network finance found so far is trade credit only, with no published referral fee [NG-044] | S11: FMCG or wholesale distributors who visit shops weekly. LEGAL: they may be paid for fund sign-ups only if they register as ARN sub-distributors (staff NISM-certified); never for insurance leads (Insurance Act s.40). The Rs 50 fee is modelled as a gold-referral fee [OWN-05, OWN-06] | T11: =B11*(1-mix_gig)/L11
A12: Non-gig · Trader associations, cooperatives, self-help groups | B12: 0.15 | C12: 20 | D12: 0.45 | E12: 0.7 | F12: 0.85 | G12: 40 | H12: 5 | I12: 0 | J12: 0 | K12: 0 | L12: =D12*E12*F12 | M12: =C12*cac_mult_ng/L12 | N12: =G12/(E12*F12) | O12: =H12/F12 | P12: =I12+J12+K12 | Q12: =M12+N12+O12+P12 | R12: assumption: no cost data found; pigmy agents are paid 2.5% of collections [NG-041] | S12: Group sessions at trader associations, cooperatives and self-help groups; each member saves into their own account (no pooling: chit rules) [REG-080]. No payment to the association for fund or insurance sales [OWN-05, OWN-06] | T12: =B12*(1-mix_gig)/L12
A13: Non-gig · Save from daily UPI sales (payment partner) | B13: 0.25 | C13: 40 | D13: 0.55 | E13: 0.8 | F13: 0.9 | G13: 40 | H13: 5 | I13: 0 | J13: 0 | K13: 30 | L13: =D13*E13*F13 | M13: =C13*cac_mult_ng/L13 | N13: =G13/(E13*F13) | O13: =H13/F13 | P13: =I13+J13+K13 | Q13: =M13+N13+O13+P13 | R13: assumption: no live product saves from a merchant's daily UPI sales [NG-046]; small merchants' UPI money lands straight in their own account [NG-030], so this is a mandate timed after the day's collections | S13: A payment partner prompts the shop to save part of each day's UPI collections. For funds, the money must settle into the shop's own bank first, then its own mandate debits [REG-066, OWN-07]. The Rs 30 is a flat service fee to the payment partner, not a commission on fund or insurance sales (legal opinion needed) | T13: =B13*(1-mix_gig)/L13
A14: Gig blended (channel mix) | B14: =SUM(B5:B9) | L14: =SUMPRODUCT($B$5:$B$9,L5:L9)/$B$14 | M14: =SUMPRODUCT($B$5:$B$9,M5:M9)/$B$14 | N14: =SUMPRODUCT($B$5:$B$9,N5:N9)/$B$14 | O14: =SUMPRODUCT($B$5:$B$9,O5:O9)/$B$14 | P14: =SUMPRODUCT($B$5:$B$9,P5:P9)/$B$14 | Q14: =SUMPRODUCT($B$5:$B$9,Q5:Q9)/$B$14
A15: Non-gig blended (channel mix) | B15: =SUM(B10:B13) | L15: =SUMPRODUCT($B$10:$B$13,L10:L13)/$B$15 | M15: =SUMPRODUCT($B$10:$B$13,M10:M13)/$B$15 | N15: =SUMPRODUCT($B$10:$B$13,N10:N13)/$B$15 | O15: =SUMPRODUCT($B$10:$B$13,O10:O13)/$B$15 | P15: =SUMPRODUCT($B$10:$B$13,P10:P13)/$B$15 | Q15: =SUMPRODUCT($B$10:$B$13,Q10:Q13)/$B$15
A16: All savers (segment mix from Inputs) | Q16: =mix_gig*cac_gig+(1-mix_gig)*cac_ng
A19: The funnel for 1,000 installs across both segments, and how many are still saving later
A20: Stage | B20: People | C20: Share of installs
A21: Installs | B21: =1000 | C21: =B21/$B$21
A22: KYC done | B22: =1000*SUMPRODUCT($T$5:$T$13,D5:D13)/SUM($T$5:$T$13) | C22: =B22/$B$21
A23: Mandate set up | B23: =1000*SUMPRODUCT($T$5:$T$13,D5:D13,E5:E13)/SUM($T$5:$T$13) | C23: =B23/$B$21
A24: First auto-debit (activated saver) | B24: =1000*SUMPRODUCT($T$5:$T$13,L5:L13)/SUM($T$5:$T$13) | C24: =B24/$B$21
A25: Still saving, month 1 | B25: =B24*(mix_gig*ret_m1+(1-mix_gig)*ret_m1_ng) | C25: =B25/$B$21
A26: Still saving, month 3 | B26: =B24*(mix_gig*ret_m3+(1-mix_gig)*ret_m3_ng) | C26: =B26/$B$21
A27: Still saving, month 6 | B27: =B24*(mix_gig*ret_m6+(1-mix_gig)*ret_m6_ng) | C27: =B27/$B$21
A28: Still saving, month 12 | B28: =B24*(mix_gig*ret_m12+(1-mix_gig)*ret_m12_ng) | C28: =B28/$B$21
A29: Still saving, month 24 | B29: =B24*(mix_gig*ret_m24+(1-mix_gig)*ret_m24_ng) | C29: =B29/$B$21

Sheet Cohort gig
A1: Cohort: the GIG savers (app delivery and ride) in one monthly cohort, followed for 60 months (scenario from Inputs!C2)
A2: Month 0 (column C) holds the starting state. Loan, card and insurance economics are booked in the month the loan, card or policy is issued. Numbers are for the whole cohort unless the row says 'per activated saver'.
A4: Month of cohort life | B4: unit | C4: 0 | D4: 1 | E4: 2 | F4: 3 | G4: 4 | H4: 5 | I4: 6 | J4: 7 | K4: 8 | L4: 9 | M4: 10 | N4: 11 | O4: 12 | P4: 13 | Q4: 14 | R4: 15 | S4: 16 | T4: 17 | U4: 18 | V4: 19 | W4: 20 | X4: 21 | Y4: 22 | Z4: 23 | AA4: 24 | AB4: 25 | AC4: 26 | AD4: 27 | AE4: 28 | AF4: 29 | AG4: 30 | AH4: 31 | AI4: 32 | AJ4: 33 | AK4: 34 | AL4: 35 | AM4: 36 | AN4: 37 | AO4: 38 | AP4: 39 | AQ4: 40 | AR4: 41 | AS4: 42 | AT4: 43 | AU4: 44 | AV4: 45 | AW4: 46 | AX4: 47 | AY4: 48 | AZ4: 49 | BA4: 50 | BB4: 51 | BC4: 52 | BD4: 53 | BE4: 54 | BF4: 55 | BG4: 56 | BH4: 57 | BI4: 58 | BJ4: 59 | BK4: 60
A5: Savers
A6: Share of activated savers still saving | B6: share | C6: 1 | D6: =IF(D$4<=1,ret_m1^D$4,IF(D$4<=3,ret_m1*(ret_m3/ret_m1)^((D$4-1)/2),IF(D$4<=6,ret_m3*(ret_m6/ret_m3)^((D$4-3)/3),IF(D$4<=12,ret_m6*(ret_m12/ret_m6)^((D$4-6)/6),IF(D$4<=24,ret_m12*(ret_m24/ret_m12)^((D$4-12)/12),ret_m24*(1-churn_late)^(D$4-24)))))) | E6: =IF(E$4<=1,ret_m1^E$4,IF(E$4<=3,ret_m1*(ret_m3/ret_m1)^((E$4-1)/2),IF(E$4<=6,ret_m3*(ret_m6/ret_m3)^((E$4-3)/3),IF(E$4<=12,ret_m6*(ret_m12/ret_m6)^((E$4-6)/6),IF(E$4<=24,ret_m12*(ret_m24/ret_m12)^((E$4-12)/12),ret_m24*(1-churn_late)^(E$4-24)))))) | F6: =IF(F$4<=1,ret_m1^F$4,IF(F$4<=3,ret_m1*(ret_m3/ret_m1)^((F$4-1)/2),IF(F$4<=6,ret_m3*(ret_m6/ret_m3)^((F$4-3)/3),IF(F$4<=12,ret_m6*(ret_m12/ret_m6)^((F$4-6)/6),IF(F$4<=24,ret_m12*(ret_m24/ret_m12)^((F$4-12)/12),ret_m24*(1-churn_late)^(F$4-24)))))) | G6: =IF(G$4<=1,ret_m1^G$4,IF(G$4<=3,ret_m1*(ret_m3/ret_m1)^((G$4-1)/2),IF(G$4<=6,ret_m3*(ret_m6/ret_m3)^((G$4-3)/3),IF(G$4<=12,ret_m6*(ret_m12/ret_m6)^((G$4-6)/6),IF(G$4<=24,ret_m12*(ret_m24/ret_m12)^((G$4-12)/12),ret_m24*(1-churn_late)^(G$4-24)))))) | H6: =IF(H$4<=1,ret_m1^H$4,IF(H$4<=3,ret_m1*(ret_m3/ret_m1)^((H$4-1)/2),IF(H$4<=6,ret_m3*(ret_m6/ret_m3)^((H$4-3)/3),IF(H$4<=12,ret_m6*(ret_m12/ret_m6)^((H$4-6)/6),IF(H$4<=24,ret_m12*(ret_m24/ret_m12)^((H$4-12)/12),ret_m24*(1-churn_late)^(H$4-24)))))) | I6: =IF(I$4<=1,ret_m1^I$4,IF(I$4<=3,ret_m1*(ret_m3/ret_m1)^((I$4-1)/2),IF(I$4<=6,ret_m3*(ret_m6/ret_m3)^((I$4-3)/3),IF(I$4<=12,ret_m6*(ret_m12/ret_m6)^((I$4-6)/6),IF(I$4<=24,ret_m12*(ret_m24/ret_m12)^((I$4-12)/12),ret_m24*(1-churn_late)^(I$4-24)))))) | J6: =IF(J$4<=1,ret_m1^J$4,IF(J$4<=3,ret_m1*(ret_m3/ret_m1)^((J$4-1)/2),IF(J$4<=6,ret_m3*(ret_m6/ret_m3)^((J$4-3)/3),IF(J$4<=12,ret_m6*(ret_m12/ret_m6)^((J$4-6)/6),IF(J$4<=24,ret_m12*(ret_m24/ret_m12)^((J$4-12)/12),ret_m24*(1-churn_late)^(J$4-24)))))) | K6: =IF(K$4<=1,ret_m1^K$4,IF(K$4<=3,ret_m1*(ret_m3/ret_m1)^((K$4-1)/2),IF(K$4<=6,ret_m3*(ret_m6/ret_m3)^((K$4-3)/3),IF(K$4<=12,ret_m6*(ret_m12/ret_m6)^((K$4-6)/6),IF(K$4<=24,ret_m12*(ret_m24/ret_m12)^((K$4-12)/12),ret_m24*(1-churn_late)^(K$4-24)))))) | ... BK6: =IF(BK$4<=1,ret_m1^BK$4,IF(BK$4<=3,ret_m1*(ret_m3/ret_m1)^((BK$4-1)/2),IF(BK$4<=6,ret_m3*(ret_m6/ret_m3)^((BK$4-3)/3),IF(BK$4<=12,ret_m6*(ret_m12/ret_m6)^((BK$4-6)/6),IF(BK$4<=24,ret_m12*(ret_m24/ret_m12)^((BK$4-12)/12),ret_m24*(1-churn_late)^(BK$4-24))))))
A7: Active savers | B7: savers | D7: =seg_n_gig*D6 | E7: =seg_n_gig*E6 | F7: =seg_n_gig*F6 | G7: =seg_n_gig*G6 | H7: =seg_n_gig*H6 | I7: =seg_n_gig*I6 | J7: =seg_n_gig*J6 | K7: =seg_n_gig*K6 | ... BK7: =seg_n_gig*BK6
A8: Money saved per active saver | B8: ₹ per month | D8: =daily_amount*(1+amount_growth)^INT((D$4-1)/12)*debits_success | E8: =daily_amount*(1+amount_growth)^INT((E$4-1)/12)*debits_success | F8: =daily_amount*(1+amount_growth)^INT((F$4-1)/12)*debits_success | G8: =daily_amount*(1+amount_growth)^INT((G$4-1)/12)*debits_success | H8: =daily_amount*(1+amount_growth)^INT((H$4-1)/12)*debits_success | I8: =daily_amount*(1+amount_growth)^INT((I$4-1)/12)*debits_success | J8: =daily_amount*(1+amount_growth)^INT((J$4-1)/12)*debits_success | K8: =daily_amount*(1+amount_growth)^INT((K$4-1)/12)*debits_success | ... BK8: =daily_amount*(1+amount_growth)^INT((BK$4-1)/12)*debits_success
A9: Money saved (contributions) | B9: ₹ | D9: =D7*D8 | E9: =E7*E8 | F9: =F7*F8 | G9: =G7*G8 | H9: =H7*H8 | I9: =I7*I8 | J9: =J7*J8 | K9: =K7*K8 | ... BK9: =BK7*BK8
A10: Balances (money sits with the fund house or bank, never with us)
A11: Share of last month's savers still saving | B11: share | D11: =D6/C6 | E11: =E6/D6 | F11: =F6/E6 | G11: =G6/F6 | H11: =H6/G6 | I11: =I6/H6 | J11: =J6/I6 | K11: =K6/J6 | ... BK11: =BK6/BJ6
A12: Last month's active balance after returns | B12: ₹ | D12: =C15*(1+fund_yield/12) | E12: =D15*(1+fund_yield/12) | F12: =E15*(1+fund_yield/12) | G12: =F15*(1+fund_yield/12) | H12: =G15*(1+fund_yield/12) | I12: =H15*(1+fund_yield/12) | J12: =I15*(1+fund_yield/12) | K12: =J15*(1+fund_yield/12) | ... BK12: =BJ15*(1+fund_yield/12)
A13: …belonging to savers who stay | B13: ₹ | D13: =D12*D11 | E13: =E12*E11 | F13: =F12*F11 | G13: =G12*G11 | H13: =H12*H11 | I13: =I12*I11 | J13: =J12*J11 | K13: =K12*K11 | ... BK13: =BK12*BK11
A14: …belonging to savers who stop this month | B14: ₹ | D14: =D12*(1-D11) | E14: =E12*(1-E11) | F14: =F12*(1-F11) | G14: =G12*(1-G11) | H14: =H12*(1-H11) | I14: =I12*(1-I11) | J14: =J12*(1-J11) | K14: =K12*(1-K11) | ... BK14: =BK12*(1-BK11)
A15: Balance of active savers | B15: ₹ | C15: 0 | D15: =D13*(1-withdraw_rate)+D9 | E15: =E13*(1-withdraw_rate)+E9 | F15: =F13*(1-withdraw_rate)+F9 | G15: =G13*(1-withdraw_rate)+G9 | H15: =H13*(1-withdraw_rate)+H9 | I15: =I13*(1-withdraw_rate)+I9 | J15: =J13*(1-withdraw_rate)+J9 | K15: =K13*(1-withdraw_rate)+K9 | ... BK15: =BK13*(1-withdraw_rate)+BK9
A16: Balance left behind by savers who stopped | B16: ₹ | C16: 0 | D16: =C16*(1+fund_yield/12)*(1-dormant_withdraw)+D14*(1-leaver_withdraw) | E16: =D16*(1+fund_yield/12)*(1-dormant_withdraw)+E14*(1-leaver_withdraw) | F16: =E16*(1+fund_yield/12)*(1-dormant_withdraw)+F14*(1-leaver_withdraw) | G16: =F16*(1+fund_yield/12)*(1-dormant_withdraw)+G14*(1-leaver_withdraw) | H16: =G16*(1+fund_yield/12)*(1-dormant_withdraw)+H14*(1-leaver_withdraw) | I16: =H16*(1+fund_yield/12)*(1-dormant_withdraw)+I14*(1-leaver_withdraw) | J16: =I16*(1+fund_yield/12)*(1-dormant_withdraw)+J14*(1-leaver_withdraw) | K16: =J16*(1+fund_yield/12)*(1-dormant_withdraw)+K14*(1-leaver_withdraw) | ... BK16: =BJ16*(1+fund_yield/12)*(1-dormant_withdraw)+BK14*(1-leaver_withdraw)
A17: Withdrawals | B17: ₹ | D17: =D13*withdraw_rate+D14*leaver_withdraw+C16*(1+fund_yield/12)*dormant_withdraw | E17: =E13*withdraw_rate+E14*leaver_withdraw+D16*(1+fund_yield/12)*dormant_withdraw | F17: =F13*withdraw_rate+F14*leaver_withdraw+E16*(1+fund_yield/12)*dormant_withdraw | G17: =G13*withdraw_rate+G14*leaver_withdraw+F16*(1+fund_yield/12)*dormant_withdraw | H17: =H13*withdraw_rate+H14*leaver_withdraw+G16*(1+fund_yield/12)*dormant_withdraw | I17: =I13*withdraw_rate+I14*leaver_withdraw+H16*(1+fund_yield/12)*dormant_withdraw | J17: =J13*withdraw_rate+J14*leaver_withdraw+I16*(1+fund_yield/12)*dormant_withdraw | K17: =K13*withdraw_rate+K14*leaver_withdraw+J16*(1+fund_yield/12)*dormant_withdraw | ... BK17: =BK13*withdraw_rate+BK14*leaver_withdraw+BJ16*(1+fund_yield/12)*dormant_withdraw
A18: Total savings balance | B18: ₹ | C18: 0 | D18: =D15+D16 | E18: =E15+E16 | F18: =F15+F16 | G18: =G15+G16 | H18: =H15+H16 | I18: =I15+I16 | J18: =J15+J16 | K18: =K15+K16 | ... BK18: =BK15+BK16
A19: …held in digital gold (lever) | B19: ₹ | C19: 0 | D19: =D18*gold_on*gold_share | E19: =E18*gold_on*gold_share | F19: =F18*gold_on*gold_share | G19: =G18*gold_on*gold_share | H19: =H18*gold_on*gold_share | I19: =I18*gold_on*gold_share | J19: =J18*gold_on*gold_share | K19: =K18*gold_on*gold_share | ... BK19: =BK18*gold_on*gold_share
A20: …held in bank FDs | B20: ₹ | C20: 0 | D20: =IF(D$4>=fd_start,(D18-D19)*fd_share,0) | E20: =IF(E$4>=fd_start,(E18-E19)*fd_share,0) | F20: =IF(F$4>=fd_start,(F18-F19)*fd_share,0) | G20: =IF(G$4>=fd_start,(G18-G19)*fd_share,0) | H20: =IF(H$4>=fd_start,(H18-H19)*fd_share,0) | I20: =IF(I$4>=fd_start,(I18-I19)*fd_share,0) | J20: =IF(J$4>=fd_start,(J18-J19)*fd_share,0) | K20: =IF(K$4>=fd_start,(K18-K19)*fd_share,0) | ... BK20: =IF(BK$4>=fd_start,(BK18-BK19)*fd_share,0)
A21: …held in the liquid fund | B21: ₹ | C21: 0 | D21: =D18-D19-D20 | E21: =E18-E19-E20 | F21: =F18-F19-F20 | G21: =G18-G19-G20 | H21: =H18-H19-H20 | I21: =I18-I19-I20 | J21: =J18-J19-J20 | K21: =K18-K19-K20 | ... BK21: =BK18-BK19-BK20
A22: Loans through partner lenders (we are the loan service provider; the lender's money)
A23: Share of active savers who have borrowed | B23: share | C23: 0 | D23: =IF(D$4>=loan_start,C23+(loan_eligible-C23)*loan_apply*loan_approval,0) | E23: =IF(E$4>=loan_start,D23+(loan_eligible-D23)*loan_apply*loan_approval,0) | F23: =IF(F$4>=loan_start,E23+(loan_eligible-E23)*loan_apply*loan_approval,0) | G23: =IF(G$4>=loan_start,F23+(loan_eligible-F23)*loan_apply*loan_approval,0) | H23: =IF(H$4>=loan_start,G23+(loan_eligible-G23)*loan_apply*loan_approval,0) | I23: =IF(I$4>=loan_start,H23+(loan_eligible-H23)*loan_apply*loan_approval,0) | J23: =IF(J$4>=loan_start,I23+(loan_eligible-I23)*loan_apply*loan_approval,0) | K23: =IF(K$4>=loan_start,J23+(loan_eligible-J23)*loan_apply*loan_approval,0) | ... BK23: =IF(BK$4>=loan_start,BJ23+(loan_eligible-BJ23)*loan_apply*loan_approval,0)
A24: Loan 1 (secured against savings): first loans | B24: loans | C24: 0 | D24: =IF(D$4>=loan_start,D7*(loan_eligible-C23)*loan_apply*loan_approval,0) | E24: =IF(E$4>=loan_start,E7*(loan_eligible-D23)*loan_apply*loan_approval,0) | F24: =IF(F$4>=loan_start,F7*(loan_eligible-E23)*loan_apply*loan_approval,0) | G24: =IF(G$4>=loan_start,G7*(loan_eligible-F23)*loan_apply*loan_approval,0) | H24: =IF(H$4>=loan_start,H7*(loan_eligible-G23)*loan_apply*loan_approval,0) | I24: =IF(I$4>=loan_start,I7*(loan_eligible-H23)*loan_apply*loan_approval,0) | J24: =IF(J$4>=loan_start,J7*(loan_eligible-I23)*loan_apply*loan_approval,0) | K24: =IF(K$4>=loan_start,K7*(loan_eligible-J23)*loan_apply*loan_approval,0) | ... BK24: =IF(BK$4>=loan_start,BK7*(loan_eligible-BJ23)*loan_apply*loan_approval,0)
A25: Loan 2 (secured): repaid loan 1, still saving, borrowed again | B25: loans | C25: 0 | D25: =IF(D$4>loan_tenor,loan_repeat*(1-ladder_dpd90)*INDEX($C$24:C$24,1,D$4-loan_tenor+1)*D6/INDEX($C$6:C$6,1,D$4-loan_tenor+1),0) | E25: =IF(E$4>loan_tenor,loan_repeat*(1-ladder_dpd90)*INDEX($C$24:D$24,1,E$4-loan_tenor+1)*E6/INDEX($C$6:D$6,1,E$4-loan_tenor+1),0) | F25: =IF(F$4>loan_tenor,loan_repeat*(1-ladder_dpd90)*INDEX($C$24:E$24,1,F$4-loan_tenor+1)*F6/INDEX($C$6:E$6,1,F$4-loan_tenor+1),0) | G25: =IF(G$4>loan_tenor,loan_repeat*(1-ladder_dpd90)*INDEX($C$24:F$24,1,G$4-loan_tenor+1)*G6/INDEX($C$6:F$6,1,G$4-loan_tenor+1),0) | H25: =IF(H$4>loan_tenor,loan_repeat*(1-ladder_dpd90)*INDEX($C$24:G$24,1,H$4-loan_tenor+1)*H6/INDEX($C$6:G$6,1,H$4-loan_tenor+1),0) | I25: =IF(I$4>loan_tenor,loan_repeat*(1-ladder_dpd90)*INDEX($C$24:H$24,1,I$4-loan_tenor+1)*I6/INDEX($C$6:H$6,1,I$4-loan_tenor+1),0) | J25: =IF(J$4>loan_tenor,loan_repeat*(1-ladder_dpd90)*INDEX($C$24:I$24,1,J$4-loan_tenor+1)*J6/INDEX($C$6:I$6,1,J$4-loan_tenor+1),0) | K25: =IF(K$4>loan_tenor,loan_repeat*(1-ladder_dpd90)*INDEX($C$24:J$24,1,K$4-loan_tenor+1)*K6/INDEX($C$6:J$6,1,K$4-loan_tenor+1),0) | ... BK25: =IF(BK$4>loan_tenor,loan_repeat*(1-ladder_dpd90)*INDEX($C$24:BJ$24,1,BK$4-loan_tenor+1)*BK6/INDEX($C$6:BJ$6,1,BK$4-loan_tenor+1),0)
A26: Loan 3 (part secured) | B26: loans | C26: 0 | D26: =IF(D$4>loan_tenor,loan_repeat*(1-ladder_dpd90)*INDEX($C$25:C$25,1,D$4-loan_tenor+1)*D6/INDEX($C$6:C$6,1,D$4-loan_tenor+1),0) | E26: =IF(E$4>loan_tenor,loan_repeat*(1-ladder_dpd90)*INDEX($C$25:D$25,1,E$4-loan_tenor+1)*E6/INDEX($C$6:D$6,1,E$4-loan_tenor+1),0) | F26: =IF(F$4>loan_tenor,loan_repeat*(1-ladder_dpd90)*INDEX($C$25:E$25,1,F$4-loan_tenor+1)*F6/INDEX($C$6:E$6,1,F$4-loan_tenor+1),0) | G26: =IF(G$4>loan_tenor,loan_repeat*(1-ladder_dpd90)*INDEX($C$25:F$25,1,G$4-loan_tenor+1)*G6/INDEX($C$6:F$6,1,G$4-loan_tenor+1),0) | H26: =IF(H$4>loan_tenor,loan_repeat*(1-ladder_dpd90)*INDEX($C$25:G$25,1,H$4-loan_tenor+1)*H6/INDEX($C$6:G$6,1,H$4-loan_tenor+1),0) | I26: =IF(I$4>loan_tenor,loan_repeat*(1-ladder_dpd90)*INDEX($C$25:H$25,1,I$4-loan_tenor+1)*I6/INDEX($C$6:H$6,1,I$4-loan_tenor+1),0) | J26: =IF(J$4>loan_tenor,loan_repeat*(1-ladder_dpd90)*INDEX($C$25:I$25,1,J$4-loan_tenor+1)*J6/INDEX($C$6:I$6,1,J$4-loan_tenor+1),0) | K26: =IF(K$4>loan_tenor,loan_repeat*(1-ladder_dpd90)*INDEX($C$25:J$25,1,K$4-loan_tenor+1)*K6/INDEX($C$6:J$6,1,K$4-loan_tenor+1),0) | ... BK26: =IF(BK$4>loan_tenor,loan_repeat*(1-ladder_dpd90)*INDEX($C$25:BJ$25,1,BK$4-loan_tenor+1)*BK6/INDEX($C$6:BJ$6,1,BK$4-loan_tenor+1),0)
A27: Loan 4 (part secured) | B27: loans | C27: 0 | D27: =IF(D$4>loan_tenor,loan_repeat*(1-ladder_dpd90)*INDEX($C$26:C$26,1,D$4-loan_tenor+1)*D6/INDEX($C$6:C$6,1,D$4-loan_tenor+1),0) | E27: =IF(E$4>loan_tenor,loan_repeat*(1-ladder_dpd90)*INDEX($C$26:D$26,1,E$4-loan_tenor+1)*E6/INDEX($C$6:D$6,1,E$4-loan_tenor+1),0) | F27: =IF(F$4>loan_tenor,loan_repeat*(1-ladder_dpd90)*INDEX($C$26:E$26,1,F$4-loan_tenor+1)*F6/INDEX($C$6:E$6,1,F$4-loan_tenor+1),0) | G27: =IF(G$4>loan_tenor,loan_repeat*(1-ladder_dpd90)*INDEX($C$26:F$26,1,G$4-loan_tenor+1)*G6/INDEX($C$6:F$6,1,G$4-loan_tenor+1),0) | H27: =IF(H$4>loan_tenor,loan_repeat*(1-ladder_dpd90)*INDEX($C$26:G$26,1,H$4-loan_tenor+1)*H6/INDEX($C$6:G$6,1,H$4-loan_tenor+1),0) | I27: =IF(I$4>loan_tenor,loan_repeat*(1-ladder_dpd90)*INDEX($C$26:H$26,1,I$4-loan_tenor+1)*I6/INDEX($C$6:H$6,1,I$4-loan_tenor+1),0) | J27: =IF(J$4>loan_tenor,loan_repeat*(1-ladder_dpd90)*INDEX($C$26:I$26,1,J$4-loan_tenor+1)*J6/INDEX($C$6:I$6,1,J$4-loan_tenor+1),0) | K27: =IF(K$4>loan_tenor,loan_repeat*(1-ladder_dpd90)*INDEX($C$26:J$26,1,K$4-loan_tenor+1)*K6/INDEX($C$6:J$6,1,K$4-loan_tenor+1),0) | ... BK27: =IF(BK$4>loan_tenor,loan_repeat*(1-ladder_dpd90)*INDEX($C$26:BJ$26,1,BK$4-loan_tenor+1)*BK6/INDEX($C$6:BJ$6,1,BK$4-loan_tenor+1),0)
A28: …first unsecured loans (loan 5) | B28: loans | C28: 0 | D28: =IF(D$4>loan_tenor,loan_repeat*(1-ladder_dpd90)*INDEX($C$27:C$27,1,D$4-loan_tenor+1)*D6/INDEX($C$6:C$6,1,D$4-loan_tenor+1),0) | E28: =IF(E$4>loan_tenor,loan_repeat*(1-ladder_dpd90)*INDEX($C$27:D$27,1,E$4-loan_tenor+1)*E6/INDEX($C$6:D$6,1,E$4-loan_tenor+1),0) | F28: =IF(F$4>loan_tenor,loan_repeat*(1-ladder_dpd90)*INDEX($C$27:E$27,1,F$4-loan_tenor+1)*F6/INDEX($C$6:E$6,1,F$4-loan_tenor+1),0) | G28: =IF(G$4>loan_tenor,loan_repeat*(1-ladder_dpd90)*INDEX($C$27:F$27,1,G$4-loan_tenor+1)*G6/INDEX($C$6:F$6,1,G$4-loan_tenor+1),0) | H28: =IF(H$4>loan_tenor,loan_repeat*(1-ladder_dpd90)*INDEX($C$27:G$27,1,H$4-loan_tenor+1)*H6/INDEX($C$6:G$6,1,H$4-loan_tenor+1),0) | I28: =IF(I$4>loan_tenor,loan_repeat*(1-ladder_dpd90)*INDEX($C$27:H$27,1,I$4-loan_tenor+1)*I6/INDEX($C$6:H$6,1,I$4-loan_tenor+1),0) | J28: =IF(J$4>loan_tenor,loan_repeat*(1-ladder_dpd90)*INDEX($C$27:I$27,1,J$4-loan_tenor+1)*J6/INDEX($C$6:I$6,1,J$4-loan_tenor+1),0) | K28: =IF(K$4>loan_tenor,loan_repeat*(1-ladder_dpd90)*INDEX($C$27:J$27,1,K$4-loan_tenor+1)*K6/INDEX($C$6:J$6,1,K$4-loan_tenor+1),0) | ... BK28: =IF(BK$4>loan_tenor,loan_repeat*(1-ladder_dpd90)*INDEX($C$27:BJ$27,1,BK$4-loan_tenor+1)*BK6/INDEX($C$6:BJ$6,1,BK$4-loan_tenor+1),0)
A29: Loans 5+ (unsecured) | B29: loans | C29: 0 | D29: =IF(D$4>loan_tenor,D28+loan_repeat*(1-ladder_dpd90)*INDEX($C$29:C$29,1,D$4-loan_tenor+1)*D6/INDEX($C$6:C$6,1,D$4-loan_tenor+1),0) | E29: =IF(E$4>loan_tenor,E28+loan_repeat*(1-ladder_dpd90)*INDEX($C$29:D$29,1,E$4-loan_tenor+1)*E6/INDEX($C$6:D$6,1,E$4-loan_tenor+1),0) | F29: =IF(F$4>loan_tenor,F28+loan_repeat*(1-ladder_dpd90)*INDEX($C$29:E$29,1,F$4-loan_tenor+1)*F6/INDEX($C$6:E$6,1,F$4-loan_tenor+1),0) | G29: =IF(G$4>loan_tenor,G28+loan_repeat*(1-ladder_dpd90)*INDEX($C$29:F$29,1,G$4-loan_tenor+1)*G6/INDEX($C$6:F$6,1,G$4-loan_tenor+1),0) | H29: =IF(H$4>loan_tenor,H28+loan_repeat*(1-ladder_dpd90)*INDEX($C$29:G$29,1,H$4-loan_tenor+1)*H6/INDEX($C$6:G$6,1,H$4-loan_tenor+1),0) | I29: =IF(I$4>loan_tenor,I28+loan_repeat*(1-ladder_dpd90)*INDEX($C$29:H$29,1,I$4-loan_tenor+1)*I6/INDEX($C$6:H$6,1,I$4-loan_tenor+1),0) | J29: =IF(J$4>loan_tenor,J28+loan_repeat*(1-ladder_dpd90)*INDEX($C$29:I$29,1,J$4-loan_tenor+1)*J6/INDEX($C$6:I$6,1,J$4-loan_tenor+1),0) | K29: =IF(K$4>loan_tenor,K28+loan_repeat*(1-ladder_dpd90)*INDEX($C$29:J$29,1,K$4-loan_tenor+1)*K6/INDEX($C$6:J$6,1,K$4-loan_tenor+1),0) | ... BK29: =IF(BK$4>loan_tenor,BK28+loan_repeat*(1-ladder_dpd90)*INDEX($C$29:BJ$29,1,BK$4-loan_tenor+1)*BK6/INDEX($C$6:BJ$6,1,BK$4-loan_tenor+1),0)
A30: Repeat loans (loans 2+) | B30: loans | C30: 0 | D30: =D25+D26+D27+D29 | E30: =E25+E26+E27+E29 | F30: =F25+F26+F27+F29 | G30: =G25+G26+G27+G29 | H30: =H25+H26+H27+H29 | I30: =I25+I26+I27+I29 | J30: =J25+J26+J27+J29 | K30: =K25+K26+K27+K29 | ... BK30: =BK25+BK26+BK27+BK29
A31: All loans | B31: loans | C31: 0 | D31: =D24+D30 | E31: =E24+E30 | F31: =F24+F30 | G31: =G24+G30 | H31: =H24+H30 | I31: =I24+I30 | J31: =J24+J30 | K31: =K24+K30 | ... BK31: =BK24+BK30
A32: Savings that can back a loan, per active saver (fund + FD; gold cannot) | B32: ₹ | C32: 0 | D32: =IF(D7>0,D15/D7,0)*(1-gold_on*gold_share) | E32: =IF(E7>0,E15/E7,0)*(1-gold_on*gold_share) | F32: =IF(F7>0,F15/F7,0)*(1-gold_on*gold_share) | G32: =IF(G7>0,G15/G7,0)*(1-gold_on*gold_share) | H32: =IF(H7>0,H15/H7,0)*(1-gold_on*gold_share) | I32: =IF(I7>0,I15/I7,0)*(1-gold_on*gold_share) | J32: =IF(J7>0,J15/J7,0)*(1-gold_on*gold_share) | K32: =IF(K7>0,K15/K7,0)*(1-gold_on*gold_share) | ... BK32: =IF(BK7>0,BK15/BK7,0)*(1-gold_on*gold_share)
A33: Secured loan size (secured_ltv of that) | B33: ₹ | C33: 0 | D33: =secured_ltv*D32 | E33: =secured_ltv*E32 | F33: =secured_ltv*F32 | G33: =secured_ltv*G32 | H33: =secured_ltv*H32 | I33: =secured_ltv*I32 | J33: =secured_ltv*J32 | K33: =secured_ltv*K32 | ... BK33: =secured_ltv*BK32
A34: Secured money lent (loans 1-4) | B34: ₹ | C34: 0 | D34: =(D24+D25+D26+D27)*D33 | E34: =(E24+E25+E26+E27)*E33 | F34: =(F24+F25+F26+F27)*F33 | G34: =(G24+G25+G26+G27)*G33 | H34: =(H24+H25+H26+H27)*H33 | I34: =(I24+I25+I26+I27)*I33 | J34: =(J24+J25+J26+J27)*J33 | K34: =(K24+K25+K26+K27)*K33 | ... BK34: =(BK24+BK25+BK26+BK27)*BK33
A35: Unsecured money lent (top-ups on loans 3-4, all of loans 5+) | B35: ₹ | C35: 0 | D35: =(D26+D27)*D33*part_unsec_multiple+D29*loan_ticket | E35: =(E26+E27)*E33*part_unsec_multiple+E29*loan_ticket | F35: =(F26+F27)*F33*part_unsec_multiple+F29*loan_ticket | G35: =(G26+G27)*G33*part_unsec_multiple+G29*loan_ticket | H35: =(H26+H27)*H33*part_unsec_multiple+H29*loan_ticket | I35: =(I26+I27)*I33*part_unsec_multiple+I29*loan_ticket | J35: =(J26+J27)*J33*part_unsec_multiple+J29*loan_ticket | K35: =(K26+K27)*K33*part_unsec_multiple+K29*loan_ticket | ... BK35: =(BK26+BK27)*BK33*part_unsec_multiple+BK29*loan_ticket
A36: Money lent (by partners, or by our NBFC if that lever is on) | B36: ₹ | C36: 0 | D36: =D34+D35 | E36: =E34+E35 | F36: =F34+F35 | G36: =G34+G35 | H36: =H34+H35 | I36: =I34+I35 | J36: =J34+J35 | K36: =K34+K35 | ... BK36: =BK34+BK35
A37: Unsecured money lent in the last loan-length months (sets the guarantee deposit) | B37: ₹ | C37: 0 | D37: =C37+D35-IF(D$4>loan_tenor,INDEX($C$35:C$35,1,D$4-loan_tenor+1),0) | E37: =D37+E35-IF(E$4>loan_tenor,INDEX($C$35:D$35,1,E$4-loan_tenor+1),0) | F37: =E37+F35-IF(F$4>loan_tenor,INDEX($C$35:E$35,1,F$4-loan_tenor+1),0) | G37: =F37+G35-IF(G$4>loan_tenor,INDEX($C$35:F$35,1,G$4-loan_tenor+1),0) | H37: =G37+H35-IF(H$4>loan_tenor,INDEX($C$35:G$35,1,H$4-loan_tenor+1),0) | I37: =H37+I35-IF(I$4>loan_tenor,INDEX($C$35:H$35,1,I$4-loan_tenor+1),0) | J37: =I37+J35-IF(J$4>loan_tenor,INDEX($C$35:I$35,1,J$4-loan_tenor+1),0) | K37: =J37+K35-IF(K$4>loan_tenor,INDEX($C$35:J$35,1,K$4-loan_tenor+1),0) | ... BK37: =BJ37+BK35-IF(BK$4>loan_tenor,INDEX($C$35:BJ$35,1,BK$4-loan_tenor+1),0)
A38: All money lent in the last loan-length months (an own NBFC's book) | B38: ₹ | C38: 0 | D38: =C38+D36-IF(D$4>loan_tenor,INDEX($C$36:C$36,1,D$4-loan_tenor+1),0) | E38: =D38+E36-IF(E$4>loan_tenor,INDEX($C$36:D$36,1,E$4-loan_tenor+1),0) | F38: =E38+F36-IF(F$4>loan_tenor,INDEX($C$36:E$36,1,F$4-loan_tenor+1),0) | G38: =F38+G36-IF(G$4>loan_tenor,INDEX($C$36:F$36,1,G$4-loan_tenor+1),0) | H38: =G38+H36-IF(H$4>loan_tenor,INDEX($C$36:G$36,1,H$4-loan_tenor+1),0) | I38: =H38+I36-IF(I$4>loan_tenor,INDEX($C$36:H$36,1,I$4-loan_tenor+1),0) | J38: =I38+J36-IF(J$4>loan_tenor,INDEX($C$36:I$36,1,J$4-loan_tenor+1),0) | K38: =J38+K36-IF(K$4>loan_tenor,INDEX($C$36:J$36,1,K$4-loan_tenor+1),0) | ... BK38: =BJ38+BK36-IF(BK$4>loan_tenor,INDEX($C$36:BJ$36,1,BK$4-loan_tenor+1),0)
A39: Capital locked: guarantee deposit, or NBFC equity for the loan book | B39: ₹ | C39: 0 | D39: =IF(nbfc_on=1,nbfc_equity*nbfc_avg_frac*D38,dlg_on*dlg_cap*D37) | E39: =IF(nbfc_on=1,nbfc_equity*nbfc_avg_frac*E38,dlg_on*dlg_cap*E37) | F39: =IF(nbfc_on=1,nbfc_equity*nbfc_avg_frac*F38,dlg_on*dlg_cap*F37) | G39: =IF(nbfc_on=1,nbfc_equity*nbfc_avg_frac*G38,dlg_on*dlg_cap*G37) | H39: =IF(nbfc_on=1,nbfc_equity*nbfc_avg_frac*H38,dlg_on*dlg_cap*H37) | I39: =IF(nbfc_on=1,nbfc_equity*nbfc_avg_frac*I38,dlg_on*dlg_cap*I37) | J39: =IF(nbfc_on=1,nbfc_equity*nbfc_avg_frac*J38,dlg_on*dlg_cap*J37) | K39: =IF(nbfc_on=1,nbfc_equity*nbfc_avg_frac*K38,dlg_on*dlg_cap*K37) | ... BK39: =IF(nbfc_on=1,nbfc_equity*nbfc_avg_frac*BK38,dlg_on*dlg_cap*BK37)
A40: Cards (issued by a partner bank)
A41: Share of active savers with an FD-secured card | B41: share | C41: 0 | D41: =IF(D$4>=card_start,C41*(1-card_churn)+(card_eligible*(1-gold_on*gold_share)-C41)*card_uptake,0) | E41: =IF(E$4>=card_start,D41*(1-card_churn)+(card_eligible*(1-gold_on*gold_share)-D41)*card_uptake,0) | F41: =IF(F$4>=card_start,E41*(1-card_churn)+(card_eligible*(1-gold_on*gold_share)-E41)*card_uptake,0) | G41: =IF(G$4>=card_start,F41*(1-card_churn)+(card_eligible*(1-gold_on*gold_share)-F41)*card_uptake,0) | H41: =IF(H$4>=card_start,G41*(1-card_churn)+(card_eligible*(1-gold_on*gold_share)-G41)*card_uptake,0) | I41: =IF(I$4>=card_start,H41*(1-card_churn)+(card_eligible*(1-gold_on*gold_share)-H41)*card_uptake,0) | J41: =IF(J$4>=card_start,I41*(1-card_churn)+(card_eligible*(1-gold_on*gold_share)-I41)*card_uptake,0) | K41: =IF(K$4>=card_start,J41*(1-card_churn)+(card_eligible*(1-gold_on*gold_share)-J41)*card_uptake,0) | ... BK41: =IF(BK$4>=card_start,BJ41*(1-card_churn)+(card_eligible*(1-gold_on*gold_share)-BJ41)*card_uptake,0)
...

Sheet Cohort non-gig
A1: Cohort: the NON-GIG savers (shopkeepers, self-employed trades, workers outside the apps, small business owners) in one monthly cohort, followed for 60 months (scenario from Inputs!C2)
A2: Month 0 (column C) holds the starting state. Loan, card and insurance economics are booked in the month the loan, card or policy is issued. Numbers are for the whole cohort unless the row says 'per activated saver'.
A4: Month of cohort life | B4: unit | C4: 0 | D4: 1 | E4: 2 | F4: 3 | G4: 4 | H4: 5 | I4: 6 | J4: 7 | K4: 8 | L4: 9 | M4: 10 | N4: 11 | O4: 12 | P4: 13 | Q4: 14 | R4: 15 | S4: 16 | T4: 17 | U4: 18 | V4: 19 | W4: 20 | X4: 21 | Y4: 22 | Z4: 23 | AA4: 24 | AB4: 25 | AC4: 26 | AD4: 27 | AE4: 28 | AF4: 29 | AG4: 30 | AH4: 31 | AI4: 32 | AJ4: 33 | AK4: 34 | AL4: 35 | AM4: 36 | AN4: 37 | AO4: 38 | AP4: 39 | AQ4: 40 | AR4: 41 | AS4: 42 | AT4: 43 | AU4: 44 | AV4: 45 | AW4: 46 | AX4: 47 | AY4: 48 | AZ4: 49 | BA4: 50 | BB4: 51 | BC4: 52 | BD4: 53 | BE4: 54 | BF4: 55 | BG4: 56 | BH4: 57 | BI4: 58 | BJ4: 59 | BK4: 60
A5: Savers
A6: Share of activated savers still saving | B6: share | C6: 1 | D6: =IF(D$4<=1,ret_m1_ng^D$4,IF(D$4<=3,ret_m1_ng*(ret_m3_ng/ret_m1_ng)^((D$4-1)/2),IF(D$4<=6,ret_m3_ng*(ret_m6_ng/ret_m3_ng)^((D$4-3)/3),IF(D$4<=12,ret_m6_ng*(ret_m12_ng/ret_m6_ng)^((D$4-6)/6),IF(D$4<=24,ret_m12_ng*(ret_m24_ng/ret_m12_ng)^((D$4-12)/12),ret_m24_ng*(1-churn_late_ng)^(D$4-24)))))) | E6: =IF(E$4<=1,ret_m1_ng^E$4,IF(E$4<=3,ret_m1_ng*(ret_m3_ng/ret_m1_ng)^((E$4-1)/2),IF(E$4<=6,ret_m3_ng*(ret_m6_ng/ret_m3_ng)^((E$4-3)/3),IF(E$4<=12,ret_m6_ng*(ret_m12_ng/ret_m6_ng)^((E$4-6)/6),IF(E$4<=24,ret_m12_ng*(ret_m24_ng/ret_m12_ng)^((E$4-12)/12),ret_m24_ng*(1-churn_late_ng)^(E$4-24)))))) | F6: =IF(F$4<=1,ret_m1_ng^F$4,IF(F$4<=3,ret_m1_ng*(ret_m3_ng/ret_m1_ng)^((F$4-1)/2),IF(F$4<=6,ret_m3_ng*(ret_m6_ng/ret_m3_ng)^((F$4-3)/3),IF(F$4<=12,ret_m6_ng*(ret_m12_ng/ret_m6_ng)^((F$4-6)/6),IF(F$4<=24,ret_m12_ng*(ret_m24_ng/ret_m12_ng)^((F$4-12)/12),ret_m24_ng*(1-churn_late_ng)^(F$4-24)))))) | G6: =IF(G$4<=1,ret_m1_ng^G$4,IF(G$4<=3,ret_m1_ng*(ret_m3_ng/ret_m1_ng)^((G$4-1)/2),IF(G$4<=6,ret_m3_ng*(ret_m6_ng/ret_m3_ng)^((G$4-3)/3),IF(G$4<=12,ret_m6_ng*(ret_m12_ng/ret_m6_ng)^((G$4-6)/6),IF(G$4<=24,ret_m12_ng*(ret_m24_ng/ret_m12_ng)^((G$4-12)/12),ret_m24_ng*(1-churn_late_ng)^(G$4-24)))))) | H6: =IF(H$4<=1,ret_m1_ng^H$4,IF(H$4<=3,ret_m1_ng*(ret_m3_ng/ret_m1_ng)^((H$4-1)/2),IF(H$4<=6,ret_m3_ng*(ret_m6_ng/ret_m3_ng)^((H$4-3)/3),IF(H$4<=12,ret_m6_ng*(ret_m12_ng/ret_m6_ng)^((H$4-6)/6),IF(H$4<=24,ret_m12_ng*(ret_m24_ng/ret_m12_ng)^((H$4-12)/12),ret_m24_ng*(1-churn_late_ng)^(H$4-24)))))) | I6: =IF(I$4<=1,ret_m1_ng^I$4,IF(I$4<=3,ret_m1_ng*(ret_m3_ng/ret_m1_ng)^((I$4-1)/2),IF(I$4<=6,ret_m3_ng*(ret_m6_ng/ret_m3_ng)^((I$4-3)/3),IF(I$4<=12,ret_m6_ng*(ret_m12_ng/ret_m6_ng)^((I$4-6)/6),IF(I$4<=24,ret_m12_ng*(ret_m24_ng/ret_m12_ng)^((I$4-12)/12),ret_m24_ng*(1-churn_late_ng)^(I$4-24)))))) | J6: =IF(J$4<=1,ret_m1_ng^J$4,IF(J$4<=3,ret_m1_ng*(ret_m3_ng/ret_m1_ng)^((J$4-1)/2),IF(J$4<=6,ret_m3_ng*(ret_m6_ng/ret_m3_ng)^((J$4-3)/3),IF(J$4<=12,ret_m6_ng*(ret_m12_ng/ret_m6_ng)^((J$4-6)/6),IF(J$4<=24,ret_m12_ng*(ret_m24_ng/ret_m12_ng)^((J$4-12)/12),ret_m24_ng*(1-churn_late_ng)^(J$4-24)))))) | K6: =IF(K$4<=1,ret_m1_ng^K$4,IF(K$4<=3,ret_m1_ng*(ret_m3_ng/ret_m1_ng)^((K$4-1)/2),IF(K$4<=6,ret_m3_ng*(ret_m6_ng/ret_m3_ng)^((K$4-3)/3),IF(K$4<=12,ret_m6_ng*(ret_m12_ng/ret_m6_ng)^((K$4-6)/6),IF(K$4<=24,ret_m12_ng*(ret_m24_ng/ret_m12_ng)^((K$4-12)/12),ret_m24_ng*(1-churn_late_ng)^(K$4-24)))))) | ... BK6: =IF(BK$4<=1,ret_m1_ng^BK$4,IF(BK$4<=3,ret_m1_ng*(ret_m3_ng/ret_m1_ng)^((BK$4-1)/2),IF(BK$4<=6,ret_m3_ng*(ret_m6_ng/ret_m3_ng)^((BK$4-3)/3),IF(BK$4<=12,ret_m6_ng*(ret_m12_ng/ret_m6_ng)^((BK$4-6)/6),IF(BK$4<=24,ret_m12_ng*(ret_m24_ng/ret_m12_ng)^((BK$4-12)/12),ret_m24_ng*(1-churn_late_ng)^(BK$4-24))))))
A7: Active savers | B7: savers | D7: =seg_n_ng*D6 | E7: =seg_n_ng*E6 | F7: =seg_n_ng*F6 | G7: =seg_n_ng*G6 | H7: =seg_n_ng*H6 | I7: =seg_n_ng*I6 | J7: =seg_n_ng*J6 | K7: =seg_n_ng*K6 | ... BK7: =seg_n_ng*BK6
A8: Money saved per active saver | B8: ₹ per month | D8: =daily_amount_ng*(1+amount_growth_ng)^INT((D$4-1)/12)*debits_success_ng | E8: =daily_amount_ng*(1+amount_growth_ng)^INT((E$4-1)/12)*debits_success_ng | F8: =daily_amount_ng*(1+amount_growth_ng)^INT((F$4-1)/12)*debits_success_ng | G8: =daily_amount_ng*(1+amount_growth_ng)^INT((G$4-1)/12)*debits_success_ng | H8: =daily_amount_ng*(1+amount_growth_ng)^INT((H$4-1)/12)*debits_success_ng | I8: =daily_amount_ng*(1+amount_growth_ng)^INT((I$4-1)/12)*debits_success_ng | J8: =daily_amount_ng*(1+amount_growth_ng)^INT((J$4-1)/12)*debits_success_ng | K8: =daily_amount_ng*(1+amount_growth_ng)^INT((K$4-1)/12)*debits_success_ng | ... BK8: =daily_amount_ng*(1+amount_growth_ng)^INT((BK$4-1)/12)*debits_success_ng
A9: Money saved (contributions) | B9: ₹ | D9: =D7*D8 | E9: =E7*E8 | F9: =F7*F8 | G9: =G7*G8 | H9: =H7*H8 | I9: =I7*I8 | J9: =J7*J8 | K9: =K7*K8 | ... BK9: =BK7*BK8
A10: Balances (money sits with the fund house or bank, never with us)
A11: Share of last month's savers still saving | B11: share | D11: =D6/C6 | E11: =E6/D6 | F11: =F6/E6 | G11: =G6/F6 | H11: =H6/G6 | I11: =I6/H6 | J11: =J6/I6 | K11: =K6/J6 | ... BK11: =BK6/BJ6
A12: Last month's active balance after returns | B12: ₹ | D12: =C15*(1+fund_yield_ng/12) | E12: =D15*(1+fund_yield_ng/12) | F12: =E15*(1+fund_yield_ng/12) | G12: =F15*(1+fund_yield_ng/12) | H12: =G15*(1+fund_yield_ng/12) | I12: =H15*(1+fund_yield_ng/12) | J12: =I15*(1+fund_yield_ng/12) | K12: =J15*(1+fund_yield_ng/12) | ... BK12: =BJ15*(1+fund_yield_ng/12)
A13: …belonging to savers who stay | B13: ₹ | D13: =D12*D11 | E13: =E12*E11 | F13: =F12*F11 | G13: =G12*G11 | H13: =H12*H11 | I13: =I12*I11 | J13: =J12*J11 | K13: =K12*K11 | ... BK13: =BK12*BK11
A14: …belonging to savers who stop this month | B14: ₹ | D14: =D12*(1-D11) | E14: =E12*(1-E11) | F14: =F12*(1-F11) | G14: =G12*(1-G11) | H14: =H12*(1-H11) | I14: =I12*(1-I11) | J14: =J12*(1-J11) | K14: =K12*(1-K11) | ... BK14: =BK12*(1-BK11)
A15: Balance of active savers | B15: ₹ | C15: 0 | D15: =D13*(1-withdraw_rate_ng)+D9 | E15: =E13*(1-withdraw_rate_ng)+E9 | F15: =F13*(1-withdraw_rate_ng)+F9 | G15: =G13*(1-withdraw_rate_ng)+G9 | H15: =H13*(1-withdraw_rate_ng)+H9 | I15: =I13*(1-withdraw_rate_ng)+I9 | J15: =J13*(1-withdraw_rate_ng)+J9 | K15: =K13*(1-withdraw_rate_ng)+K9 | ... BK15: =BK13*(1-withdraw_rate_ng)+BK9
A16: Balance left behind by savers who stopped | B16: ₹ | C16: 0 | D16: =C16*(1+fund_yield_ng/12)*(1-dormant_withdraw_ng)+D14*(1-leaver_withdraw_ng) | E16: =D16*(1+fund_yield_ng/12)*(1-dormant_withdraw_ng)+E14*(1-leaver_withdraw_ng) | F16: =E16*(1+fund_yield_ng/12)*(1-dormant_withdraw_ng)+F14*(1-leaver_withdraw_ng) | G16: =F16*(1+fund_yield_ng/12)*(1-dormant_withdraw_ng)+G14*(1-leaver_withdraw_ng) | H16: =G16*(1+fund_yield_ng/12)*(1-dormant_withdraw_ng)+H14*(1-leaver_withdraw_ng) | I16: =H16*(1+fund_yield_ng/12)*(1-dormant_withdraw_ng)+I14*(1-leaver_withdraw_ng) | J16: =I16*(1+fund_yield_ng/12)*(1-dormant_withdraw_ng)+J14*(1-leaver_withdraw_ng) | K16: =J16*(1+fund_yield_ng/12)*(1-dormant_withdraw_ng)+K14*(1-leaver_withdraw_ng) | ... BK16: =BJ16*(1+fund_yield_ng/12)*(1-dormant_withdraw_ng)+BK14*(1-leaver_withdraw_ng)
A17: Withdrawals | B17: ₹ | D17: =D13*withdraw_rate_ng+D14*leaver_withdraw_ng+C16*(1+fund_yield_ng/12)*dormant_withdraw_ng | E17: =E13*withdraw_rate_ng+E14*leaver_withdraw_ng+D16*(1+fund_yield_ng/12)*dormant_withdraw_ng | F17: =F13*withdraw_rate_ng+F14*leaver_withdraw_ng+E16*(1+fund_yield_ng/12)*dormant_withdraw_ng | G17: =G13*withdraw_rate_ng+G14*leaver_withdraw_ng+F16*(1+fund_yield_ng/12)*dormant_withdraw_ng | H17: =H13*withdraw_rate_ng+H14*leaver_withdraw_ng+G16*(1+fund_yield_ng/12)*dormant_withdraw_ng | I17: =I13*withdraw_rate_ng+I14*leaver_withdraw_ng+H16*(1+fund_yield_ng/12)*dormant_withdraw_ng | J17: =J13*withdraw_rate_ng+J14*leaver_withdraw_ng+I16*(1+fund_yield_ng/12)*dormant_withdraw_ng | K17: =K13*withdraw_rate_ng+K14*leaver_withdraw_ng+J16*(1+fund_yield_ng/12)*dormant_withdraw_ng | ... BK17: =BK13*withdraw_rate_ng+BK14*leaver_withdraw_ng+BJ16*(1+fund_yield_ng/12)*dormant_withdraw_ng
A18: Total savings balance | B18: ₹ | C18: 0 | D18: =D15+D16 | E18: =E15+E16 | F18: =F15+F16 | G18: =G15+G16 | H18: =H15+H16 | I18: =I15+I16 | J18: =J15+J16 | K18: =K15+K16 | ... BK18: =BK15+BK16
A19: …held in digital gold (lever) | B19: ₹ | C19: 0 | D19: =D18*gold_on_ng*gold_share_ng | E19: =E18*gold_on_ng*gold_share_ng | F19: =F18*gold_on_ng*gold_share_ng | G19: =G18*gold_on_ng*gold_share_ng | H19: =H18*gold_on_ng*gold_share_ng | I19: =I18*gold_on_ng*gold_share_ng | J19: =J18*gold_on_ng*gold_share_ng | K19: =K18*gold_on_ng*gold_share_ng | ... BK19: =BK18*gold_on_ng*gold_share_ng
A20: …held in bank FDs | B20: ₹ | C20: 0 | D20: =IF(D$4>=fd_start_ng,(D18-D19)*fd_share_ng,0) | E20: =IF(E$4>=fd_start_ng,(E18-E19)*fd_share_ng,0) | F20: =IF(F$4>=fd_start_ng,(F18-F19)*fd_share_ng,0) | G20: =IF(G$4>=fd_start_ng,(G18-G19)*fd_share_ng,0) | H20: =IF(H$4>=fd_start_ng,(H18-H19)*fd_share_ng,0) | I20: =IF(I$4>=fd_start_ng,(I18-I19)*fd_share_ng,0) | J20: =IF(J$4>=fd_start_ng,(J18-J19)*fd_share_ng,0) | K20: =IF(K$4>=fd_start_ng,(K18-K19)*fd_share_ng,0) | ... BK20: =IF(BK$4>=fd_start_ng,(BK18-BK19)*fd_share_ng,0)
A21: …held in the liquid fund | B21: ₹ | C21: 0 | D21: =D18-D19-D20 | E21: =E18-E19-E20 | F21: =F18-F19-F20 | G21: =G18-G19-G20 | H21: =H18-H19-H20 | I21: =I18-I19-I20 | J21: =J18-J19-J20 | K21: =K18-K19-K20 | ... BK21: =BK18-BK19-BK20
A22: Loans through partner lenders (we are the loan service provider; the lender's money)
A23: Share of active savers who have borrowed | B23: share | C23: 0 | D23: =IF(D$4>=loan_start_ng,C23+(loan_eligible_ng-C23)*loan_apply_ng*loan_approval_ng,0) | E23: =IF(E$4>=loan_start_ng,D23+(loan_eligible_ng-D23)*loan_apply_ng*loan_approval_ng,0) | F23: =IF(F$4>=loan_start_ng,E23+(loan_eligible_ng-E23)*loan_apply_ng*loan_approval_ng,0) | G23: =IF(G$4>=loan_start_ng,F23+(loan_eligible_ng-F23)*loan_apply_ng*loan_approval_ng,0) | H23: =IF(H$4>=loan_start_ng,G23+(loan_eligible_ng-G23)*loan_apply_ng*loan_approval_ng,0) | I23: =IF(I$4>=loan_start_ng,H23+(loan_eligible_ng-H23)*loan_apply_ng*loan_approval_ng,0) | J23: =IF(J$4>=loan_start_ng,I23+(loan_eligible_ng-I23)*loan_apply_ng*loan_approval_ng,0) | K23: =IF(K$4>=loan_start_ng,J23+(loan_eligible_ng-J23)*loan_apply_ng*loan_approval_ng,0) | ... BK23: =IF(BK$4>=loan_start_ng,BJ23+(loan_eligible_ng-BJ23)*loan_apply_ng*loan_approval_ng,0)
A24: Loan 1 (secured against savings): first loans | B24: loans | C24: 0 | D24: =IF(D$4>=loan_start_ng,D7*(loan_eligible_ng-C23)*loan_apply_ng*loan_approval_ng,0) | E24: =IF(E$4>=loan_start_ng,E7*(loan_eligible_ng-D23)*loan_apply_ng*loan_approval_ng,0) | F24: =IF(F$4>=loan_start_ng,F7*(loan_eligible_ng-E23)*loan_apply_ng*loan_approval_ng,0) | G24: =IF(G$4>=loan_start_ng,G7*(loan_eligible_ng-F23)*loan_apply_ng*loan_approval_ng,0) | H24: =IF(H$4>=loan_start_ng,H7*(loan_eligible_ng-G23)*loan_apply_ng*loan_approval_ng,0) | I24: =IF(I$4>=loan_start_ng,I7*(loan_eligible_ng-H23)*loan_apply_ng*loan_approval_ng,0) | J24: =IF(J$4>=loan_start_ng,J7*(loan_eligible_ng-I23)*loan_apply_ng*loan_approval_ng,0) | K24: =IF(K$4>=loan_start_ng,K7*(loan_eligible_ng-J23)*loan_apply_ng*loan_approval_ng,0) | ... BK24: =IF(BK$4>=loan_start_ng,BK7*(loan_eligible_ng-BJ23)*loan_apply_ng*loan_approval_ng,0)
A25: Loan 2 (secured): repaid loan 1, still saving, borrowed again | B25: loans | C25: 0 | D25: =IF(D$4>loan_tenor_ng,loan_repeat_ng*(1-ladder_dpd90_ng)*INDEX($C$24:C$24,1,D$4-loan_tenor_ng+1)*D6/INDEX($C$6:C$6,1,D$4-loan_tenor_ng+1),0) | E25: =IF(E$4>loan_tenor_ng,loan_repeat_ng*(1-ladder_dpd90_ng)*INDEX($C$24:D$24,1,E$4-loan_tenor_ng+1)*E6/INDEX($C$6:D$6,1,E$4-loan_tenor_ng+1),0) | F25: =IF(F$4>loan_tenor_ng,loan_repeat_ng*(1-ladder_dpd90_ng)*INDEX($C$24:E$24,1,F$4-loan_tenor_ng+1)*F6/INDEX($C$6:E$6,1,F$4-loan_tenor_ng+1),0) | G25: =IF(G$4>loan_tenor_ng,loan_repeat_ng*(1-ladder_dpd90_ng)*INDEX($C$24:F$24,1,G$4-loan_tenor_ng+1)*G6/INDEX($C$6:F$6,1,G$4-loan_tenor_ng+1),0) | H25: =IF(H$4>loan_tenor_ng,loan_repeat_ng*(1-ladder_dpd90_ng)*INDEX($C$24:G$24,1,H$4-loan_tenor_ng+1)*H6/INDEX($C$6:G$6,1,H$4-loan_tenor_ng+1),0) | I25: =IF(I$4>loan_tenor_ng,loan_repeat_ng*(1-ladder_dpd90_ng)*INDEX($C$24:H$24,1,I$4-loan_tenor_ng+1)*I6/INDEX($C$6:H$6,1,I$4-loan_tenor_ng+1),0) | J25: =IF(J$4>loan_tenor_ng,loan_repeat_ng*(1-ladder_dpd90_ng)*INDEX($C$24:I$24,1,J$4-loan_tenor_ng+1)*J6/INDEX($C$6:I$6,1,J$4-loan_tenor_ng+1),0) | K25: =IF(K$4>loan_tenor_ng,loan_repeat_ng*(1-ladder_dpd90_ng)*INDEX($C$24:J$24,1,K$4-loan_tenor_ng+1)*K6/INDEX($C$6:J$6,1,K$4-loan_tenor_ng+1),0) | ... BK25: =IF(BK$4>loan_tenor_ng,loan_repeat_ng*(1-ladder_dpd90_ng)*INDEX($C$24:BJ$24,1,BK$4-loan_tenor_ng+1)*BK6/INDEX($C$6:BJ$6,1,BK$4-loan_tenor_ng+1),0)
A26: Loan 3 (part secured) | B26: loans | C26: 0 | D26: =IF(D$4>loan_tenor_ng,loan_repeat_ng*(1-ladder_dpd90_ng)*INDEX($C$25:C$25,1,D$4-loan_tenor_ng+1)*D6/INDEX($C$6:C$6,1,D$4-loan_tenor_ng+1),0) | E26: =IF(E$4>loan_tenor_ng,loan_repeat_ng*(1-ladder_dpd90_ng)*INDEX($C$25:D$25,1,E$4-loan_tenor_ng+1)*E6/INDEX($C$6:D$6,1,E$4-loan_tenor_ng+1),0) | F26: =IF(F$4>loan_tenor_ng,loan_repeat_ng*(1-ladder_dpd90_ng)*INDEX($C$25:E$25,1,F$4-loan_tenor_ng+1)*F6/INDEX($C$6:E$6,1,F$4-loan_tenor_ng+1),0) | G26: =IF(G$4>loan_tenor_ng,loan_repeat_ng*(1-ladder_dpd90_ng)*INDEX($C$25:F$25,1,G$4-loan_tenor_ng+1)*G6/INDEX($C$6:F$6,1,G$4-loan_tenor_ng+1),0) | H26: =IF(H$4>loan_tenor_ng,loan_repeat_ng*(1-ladder_dpd90_ng)*INDEX($C$25:G$25,1,H$4-loan_tenor_ng+1)*H6/INDEX($C$6:G$6,1,H$4-loan_tenor_ng+1),0) | I26: =IF(I$4>loan_tenor_ng,loan_repeat_ng*(1-ladder_dpd90_ng)*INDEX($C$25:H$25,1,I$4-loan_tenor_ng+1)*I6/INDEX($C$6:H$6,1,I$4-loan_tenor_ng+1),0) | J26: =IF(J$4>loan_tenor_ng,loan_repeat_ng*(1-ladder_dpd90_ng)*INDEX($C$25:I$25,1,J$4-loan_tenor_ng+1)*J6/INDEX($C$6:I$6,1,J$4-loan_tenor_ng+1),0) | K26: =IF(K$4>loan_tenor_ng,loan_repeat_ng*(1-ladder_dpd90_ng)*INDEX($C$25:J$25,1,K$4-loan_tenor_ng+1)*K6/INDEX($C$6:J$6,1,K$4-loan_tenor_ng+1),0) | ... BK26: =IF(BK$4>loan_tenor_ng,loan_repeat_ng*(1-ladder_dpd90_ng)*INDEX($C$25:BJ$25,1,BK$4-loan_tenor_ng+1)*BK6/INDEX($C$6:BJ$6,1,BK$4-loan_tenor_ng+1),0)
