Workbook
Name in_signups_run: 'Inputs'!$C$3
Name in_ramp_months: 'Inputs'!$C$4
Name in_r3: 'Inputs'!$C$6
Name in_r12: 'Inputs'!$C$7
Name in_churn_late: 'Inputs'!$C$8
Name in_daily: 'Inputs'!$C$10
Name in_days: 'Inputs'!$C$11
Name in_amount_growth: 'Inputs'!$C$12
Name in_term: 'Inputs'!$C$14
Name in_rollover: 'Inputs'!$C$15
Name in_withdraw_m: 'Inputs'!$C$16
Name in_trail: 'Inputs'!$C$17
Name in_fund_return: 'Inputs'!$C$18
Name in_early_takeup_mult: 'Inputs'!$C$20
Name in_early_approval_mult: 'Inputs'!$C$21
Name in_signup_growth: 'Inputs'!$C$23
Name in_takeup_growth: 'Inputs'!$C$24
Name in_approval_growth: 'Inputs'!$C$25
Name in_ticket_growth: 'Inputs'!$C$26
Name in_topup_share: 'Inputs'!$C$27
Name in_topup_size: 'Inputs'!$C$28
Name in_upi_12: 'Inputs'!$C$30
Name in_upi_ramp: 'Inputs'!$C$31
Name in_visit_every: 'Inputs'!$C$32
Name in_capacity: 'Inputs'!$C$33
Name in_extra_capacity_cost: 'Inputs'!$C$34
Name in_apply: 'Inputs'!$C$36
Name in_eligible: 'Inputs'!$C$37
Name in_approved_first: 'Inputs'!$C$38
Name in_approved_repeat: 'Inputs'!$C$39
Name in_tenure: 'Inputs'!$C$40
Name in_ticket: 'Inputs'!$C$41
Name in_fee: 'Inputs'!$C$42
Name in_taken_back: 'Inputs'!$C$43
Name in_rate: 'Inputs'!$C$44
Name in_loss: 'Inputs'!$C$45
Name in_leaver_loan: 'Inputs'!$C$46
Name in_owed: 'Inputs'!$C$48
Name in_recovered: 'Inputs'!$C$49
Name in_early_cured: 'Inputs'!$C$50
Name in_fee_early: 'Inputs'!$C$51
Name in_fee_b3: 'Inputs'!$C$52
Name in_card_share: 'Inputs'!$C$54
Name in_card_fee: 'Inputs'!$C$55
Name in_hlth_small_takeup: 'Inputs'!$C$57
Name in_hlth_small_ticket: 'Inputs'!$C$58
Name in_hlth_small_comm: 'Inputs'!$C$59
Name in_hlth_small_renew: 'Inputs'!$C$60
Name in_hlth_small_renew_comm: 'Inputs'!$C$61
Name in_hlth_family_takeup: 'Inputs'!$C$63
Name in_hlth_family_ticket: 'Inputs'!$C$64
Name in_hlth_family_comm: 'Inputs'!$C$65
Name in_hlth_family_renew: 'Inputs'!$C$66
Name in_hlth_family_renew_comm: 'Inputs'!$C$67
Name in_life_term_takeup: 'Inputs'!$C$69
Name in_life_term_ticket: 'Inputs'!$C$70
Name in_life_term_comm: 'Inputs'!$C$71
Name in_life_term_renew: 'Inputs'!$C$72
Name in_life_term_renew_comm: 'Inputs'!$C$73
Name in_accident_takeup: 'Inputs'!$C$75

Sheet Read me
A1: Cohort model: one street agent, 60 months, one cohort of sign-ups a month
A3: WHAT TO EDIT
A4: Only the BLUE cells on the Inputs sheet (column C, 'Likely'). Yellow-filled blue cells are operator decisions or open choices (still saving at month 12, the fund commission, card share, loan tenure, sign-ups). Low / High / Shape beside them are the Monte Carlo ranges, shown for reference; the formulas use only the Likely column. Every cell comment says where the number comes from.
A5: Example: to test 40 of 100 still saving at month 12, type 0.40 into 'Still saving at month 12'; the Summary NPVs move at once.
A6: Black = formulas. Green = a link to another sheet. Nothing else should be typed over.
A8: HOW THE SHEETS FLOW
A9: Inputs -> Retention curve (ages 1-60) -> Age profile (one sign-up's saving, fund, UPI and KYC lines by age) -> Sign-ups by age (which cohort is which age in each month) -> Cohort x age (the marketplace lines - loans, top-ups, cards, the 17 products and collections - one row per cohort and age, because take-up and approvals grow with the calendar year) -> Monthly (age-profile lines = SUMPRODUCT with Sign-ups by age; marketplace lines = SUMIFS of Cohort x age by calendar month; then salary, extra capacity, KYC, the P&L, the discount factor and NPV) -> Summary. Cohort triangle shows savers still saving by cohort and month.
A11: HOW IT IS BUILT (approximations, also in model/cohort_engine.py)
A12: Retention: drop-off at a steady monthly rate within months 1-3 (to r3), 4-12 (to r12), then churn_late. A saver who stops withdraws his whole balance. The balance builds over a 12-month term; at a term end the rollover share stays, the rest is paid out; a share is withdrawn mid-term each month.
A13: Marketplace: loans, cards and all 17 products are offered from month 1 (Inputs: first month a saver is offered; the operator, 16 Oct: 'the marketplace opens as soon as possible... It's not at our cost'). There is no marketplace cost line: costs are salary, extra capacity, KYC per sign-up and support (0).
A14: Loans: savers offered the marketplace (still saving) with no loan running apply at a monthly hazard; first loans use the first-loan approval, repeat loans the repeat approval. A borrower is out of the applicant pool while his loan runs (tenure rounded to whole months) and returns, if still saving, the month after it ends. Churn does not depend on having a loan. A saver who stops keeps paying, gets no repeat.
A15: Overdue loans: p90 = loss / (owed x (1 - recovered)) is the share of loans that ever go 90+ days bad. Fees per loan made = early_cured x fee_early, paid ~9 months after the loan, plus p90 x recovered x fee_b3, paid ~18 months after; fees due after month 60 are not counted. The lender carries the loss itself. Insurance commissions sit at the IRDAI draft distributor caps.
... A28: Inputs not yet in dist_agreed_v1.csv (taken from COHORT_INPUTS and its addenda): 3 keys, e.g. nps_comm, recharge_renew, bills_renew.

Sheet Summary
A1: One street agent, 60 months: cumulative P&L at the likely values (undiscounted)
A2: Every number in this first block is a formula on the other sheets; change a blue cell on Inputs and it moves. Built 2026-10-16 by model/build_cohort_xlsx.py.
A4: Measure | B4: Value | C4: Unit
A5: Cumulative P&L at 36 months | B5: =INDEX(Monthly!BH2:BH61,36) | C5: Rs, undiscounted (operator, round 5)
A6: Cumulative P&L at 60 months | B6: =INDEX(Monthly!BH2:BH61,60) | C6: Rs, undiscounted
A7: Payback month (cumulative P&L turns positive) | B7: =IF(MIN(Monthly!BJ2:BJ61)>60,"never within 60 months",MIN(Monthly!BJ2:BJ61)) | C7: month (and stays positive)
A8: Peak cash need (lowest cumulative P&L) | B8: =MIN(0,MIN(Monthly!BH2:BH61)) | C8: Rs (negative: the cash needed is its size)
A9: NPV (legacy, 20% discount): NPV at 36 months | B9: =SUMPRODUCT(Monthly!BD2:BD37,Monthly!BK2:BK37) | C9: Rs, reference only
A10: NPV (legacy, 20% discount): NPV at 60 months | B10: =SUMPRODUCT(Monthly!BD2:BD61,Monthly!BK2:BK61) | C10: Rs, reference only
A11: Our fees on home loans and LAP in 60 months | B11: =SUM(Monthly!AT2:AT61)+SUM(Monthly!AU2:AU61) | C11: Rs
A12: Agent pay on balance, 60 months | B12: =SUM(Monthly!BB2:BB61) | C12: Rs (0.25% a year of his savers' balance)
A13: Value per sign-up, his first 5 years, discounted to his sign-up month (a month-1 sign-up) | B13: =SUM('Age profile'!U2:U61)+SUMPRODUCT('Cohort x age'!CE2:CE61,'Age profile'!T2:T61)/INDEX(Monthly!B2:B61,1) | C13: Rs (before the agent's salary)
A14: Agent's salary per sign-up (for comparison) | B14: =in_salary/in_signups_run | C14: Rs
A15: Year-1 P&L (months 1-12) | B15: =SUM(Monthly!BD2:BD13) | C15: Rs
A16: Cumulative cash at month 60 | B16: =INDEX(Monthly!BH2:BH61,60) | C16: Rs
A17: Savers still saving at month 60 | B17: =INDEX(Monthly!C2:C61,60) | C17: savers
A18: Peak cash visits a day | B18: =MAX(Monthly!G2:G61) | C18: visits a day
A19: Share of savers on UPI at month 60 | B19: =INDEX(Monthly!H2:H61,60) | C19: share
A20: UPI share needed at month 60 to stay within one agent's visits | B20: =INDEX(Monthly!I2:I61,60) | C20: share
A21: Extra capacity cost in month 60 | B21: =INDEX(Monthly!AX2:AX61,60) | C21: Rs a month
A22: Extra capacity cost, 60 months, not discounted | B22: =SUM(Monthly!AX2:AX61) | C22: Rs
A23: Extra capacity cost, 60 months, discounted | B23: =SUMPRODUCT(Monthly!AX2:AX61,Monthly!BE2:BE61) | C23: Rs
A24: Loans per 100 savers offered the marketplace, a year (first + repeat) | B24: =100*SUM(Monthly!O2:O61)/(SUM(Monthly!E2:E61)/12) | C24: loans
A25: Loans made in 60 months | B25: =SUM(Monthly!O2:O61) | C25: loans
A26: Implied share of loans that ever go 90+ days bad (p90) | B26: =d_p90 | C26: CRIF NG-015 10.2%; MAC-03 3.6%
A27: Early brought back + p90 | B27: =d_check | C27: page check: at most 50%
A28: Page check | B28: =d_check_flag
A29: 31-90 day collection fees per loan made | B29: =d_dpd | C29: Rs a loan, paid ~9 months after the loan
A30: 90+ recovery fees per loan made | B30: =d_rec | C30: Rs a loan, paid ~18 months after the loan
A31: Cross-sell money per saver offered the marketplace, a year, all 17 products (old: Rs 63) | B31: =(SUM(Monthly!AC2:AC61)+SUM(Monthly!AD2:AD61)+SUM(Monthly!AE2:AE61)+SUM(Monthly!AF2:AF61)+SUM(Monthly!AG2:AG61)+SUM(Monthly!AH2:AH61)+SUM(Monthly!AI2:AI61)+SUM(Monthly!AJ2:AJ61)+SUM(Monthly!AK2:AK61)+SUM(Monthly!AL2:AL61)+SUM(Monthly!AM2:AM61)+SUM(Monthly!AN2:AN61)+SUM(Monthly!AO2:AO61)+SUM(Monthly!AP2:AP61)+SUM(Monthly!AQ2:AQ61)+SUM(Monthly!AR2:AR61)+SUM(Monthly!AS2:AS61)+SUM(Monthly!AT2:AT61)+SUM(Monthly!AU2:AU61))/(SUM(Monthly!E2:E61)/12) | C31: Rs a saver offered, a year (60-month book)
A32: Small health / hospital cash | B32: =SUM(Monthly!AC2:AC61)/(SUM(Monthly!E2:E61)/12) | C32: Rs a saver offered, a year
A33: Family health cover | B33: =SUM(Monthly!AD2:AD61)/(SUM(Monthly!E2:E61)/12) | C33: Rs a saver offered, a year
A34: Term life (small cover) | B34: =SUM(Monthly!AE2:AE61)/(SUM(Monthly!E2:E61)/12) | C34: Rs a saver offered, a year
A35: Personal accident | B35: =SUM(Monthly!AF2:AF61)/(SUM(Monthly!E2:E61)/12) | C35: Rs a saver offered, a year
A36: Two-wheeler insurance | B36: =SUM(Monthly!AG2:AG61)/(SUM(Monthly!E2:E61)/12) | C36: Rs a saver offered, a year
A37: Mobile / device insurance | B37: =SUM(Monthly!AH2:AH61)/(SUM(Monthly!E2:E61)/12) | C37: Rs a saver offered, a year
A38: Shop insurance (fire and burglary) | B38: =SUM(Monthly!AI2:AI61)/(SUM(Monthly!E2:E61)/12) | C38: Rs a saver offered, a year
A39: Equity/hybrid SIP trail | B39: =SUM(Monthly!AJ2:AJ61)/(SUM(Monthly!E2:E61)/12) | C39: Rs a saver offered, a year
A40: Choti SIP incentive | B40: =SUM(Monthly!AK2:AK61)/(SUM(Monthly!E2:E61)/12) | C40: Rs a saver offered, a year
A41: NPS | B41: =SUM(Monthly!AL2:AL61)/(SUM(Monthly!E2:E61)/12) | C41: Rs a saver offered, a year
...

Sheet Inputs
A1: Group | B1: Input | C1: Likely (edit me) | D1: Low | E1: High | F1: Shape | G1: Unit | H1: Key | I1: Where the number comes from
A2: Sign-ups
B3: Sign-ups a month once up to speed | C3: 30 | D3: 20 | E3: 45 | F3: pert | G3: sign-ups a month | H3: signups_run | I3: dist_agreed_v1.csv
B4: Months for a new agent to reach full speed | C4: 3 | D4: 0 | E4: 6 | F4: triangular | G4: months | H4: ramp_months | I4: dist_agreed_v1.csv
A5: Retention
B6: Still saving at month 3 | C6: 0.8 | D6: 0.6 | E6: 0.92 | F6: pert | G6: share | H6: r3 | I6: dist_agreed_v1.csv
B7: Still saving at month 12 | C7: 0.55 | D7: 0.25 | E7: 0.72 | F7: pert | G7: share | H7: r12 | I7: dist_agreed_v1.csv (file matches the operator decision)
B8: Monthly drop-off after month 12 | C8: 0.015 | D8: 0.01 | E8: 0.03 | F8: pert | G8: share | H8: churn_late | I8: dist_agreed_v1.csv
A9: Saving
B10: Daily amount at sign-up (Rs) | C10: 350 | D10: 200 | E10: 500 | F10: triangular | G10: Rs a day | H10: daily | I10: dist_agreed_v1.csv
B11: Deposit days a month | C11: 20 | D11: 16 | E11: 24 | F11: pert | G11: days a month | H11: days | I11: dist_agreed_v1.csv
B12: Growth in his daily amount per year saved | C12: 0.05 | D12: 0 | E12: 0.1 | F12: pert | G12: share | H12: amount_growth | I12: dist_agreed_v1.csv
A13: The fund
B14: Savings term (months) | C14: 12 | D14: 12 | E14: 12 | F14: fixed | G14: months | H14: term | I14: dist_agreed_v1.csv
B15: Share of the balance left in the fund at each term end | C15: 0.25 | D15: 0 | E15: 0.6 | F15: pert | G15: share | H15: rollover | I15: dist_agreed_v1.csv
B16: Share of the balance withdrawn mid-term, each month | C16: 0.01 | D16: 0 | E16: 0.03 | F16: pert | G16: share | H16: withdraw_m | I16: dist_agreed_v1.csv
B17: Fund commission a year (debt fund) | C17: 0.0035 | D17: 0.002 | E17: 0.005 | F17: pert | G17: share | H17: trail | I17: dist_agreed_v1.csv (file matches the operator decision)
B18: Saver's net return on the fund, a year | C18: 0.07 | D18: 0.06 | E18: 0.075 | F18: pert | G18: share | H18: fund_return | I18: dist_agreed_v1.csv
A19: Early months (a saver's months 1-6)
B20: Take-up factor in a saver's months 1-6 | C20: 0.5 | D20: 0.25 | E20: 0.75 | F20: pert | G20: share | H20: early_takeup_mult | I20: dist_agreed_v1.csv
B21: Approval factor in a saver's months 1-6 (first loans, cards) | C21: 0.6 | D21: 0.4 | E21: 0.8 | F21: pert | G21: share | H21: early_approval_mult | I21: dist_agreed_v1.csv
A22: Growth with the pool's history (addendum 4)
B23: Sign-ups grow each year from year 2 (cap 100 a month) | C23: 0.1 | D23: 0 | E23: 0.2 | F23: pert | G23: share | H23: signup_growth | I23: dist_agreed_v1.csv
B24: Every take-up rises each calendar year with the pool's history (cap 2x) | C24: 0.05 | D24: 0 | E24: 0.15 | F24: pert | G24: share | H24: takeup_growth | I24: dist_agreed_v1.csv
B25: First-loan and card approval rise each calendar year (cap 80% absolute) | C25: 0.1 | D25: 0 | E25: 0.2 | F25: pert | G25: share | H25: approval_growth | I25: dist_agreed_v1.csv
B26: Next loan bigger for each year repaid (cap Rs 5 lakh) | C26: 0.1 | D26: 0 | E26: 0.2 | F26: pert | G26: share | H26: ticket_growth | I26: dist_agreed_v1.csv
B27: Borrowers with 12+ EMIs paid who take a top-up, a year | C27: 0.15 | D27: 0.05 | E27: 0.3 | F27: pert | G27: share | H27: topup_share | I27: dist_agreed_v1.csv
B28: Top-up size, share of his original ticket | C28: 0.4 | D28: 0.25 | E28: 0.6 | F28: pert | G28: share | H28: topup_size | I28: dist_agreed_v1.csv
A29: UPI and cash visits
B30: Share of active savers on UPI by month 12 | C30: 0.3 | D30: 0.1 | E30: 0.6 | F30: pert | G30: share | H30: upi_12 | I30: dist_agreed_v1.csv
B31: Age at which the UPI share reaches its month-12 level | C31: 12 | D31: 12 | E31: 12 | F31: fixed | G31: age (months) | H31: upi_ramp | I31: dist_agreed_v1.csv
B32: Days between cash visits | C32: 2.5 | D32: 2.5 | E32: 2.5 | F32: fixed | G32: days | H32: visit_every | I32: dist_agreed_v1.csv
B33: Cash visits one agent can make a day | C33: 400 | D33: 300 | E33: 450 | F33: triangular | G33: visits a day | H33: capacity | I33: dist_agreed_v1.csv
B34: Extra capacity cost a month per 400 visits a day (Rs) | C34: 20000 | D34: 20000 | E34: 20000 | F34: fixed | G34: Rs a month | H34: extra_capacity_cost | I34: dist_agreed_v1.csv
A35: Loans
B36: Proven savers with no loan running who apply, a year | C36: 0.18 | D36: 0.08 | E36: 0.35 | F36: pert | G36: share a year | H36: apply | I36: dist_agreed_v1.csv
B37: Applicants eligible | C37: 0.45 | D37: 0.25 | E37: 0.65 | F37: pert | G37: share | H37: eligible | I37: dist_agreed_v1.csv
B38: Approved, first loan | C38: 0.35 | D38: 0.2 | E38: 0.5 | F38: pert | G38: share | H38: approved_first | I38: dist_agreed_v1.csv
B39: Approved, repeat loan | C39: 0.7 | D39: 0.5 | E39: 0.85 | F39: pert | G39: share | H39: approved_repeat | I39: dist_agreed_v1.csv
B40: Loan tenure (months) | C40: 36 | D40: 24 | E40: 48 | F40: pert | G40: months | H40: tenure | I40: dist_agreed_v1.csv (file matches the operator decision)
...

Sheet Retention curve
A1: Age (month since sign-up) | B1: Monthly drop-off after this month | C1: Still saving (share of sign-ups) | D1: Stopped this month
A2: 1 | B2: =IF(A2<=3,d_h1,IF(A2<=12,d_h2,in_churn_late)) | C2: 1 | D2: 0
A3: 2 | B3: =IF(A3<=3,d_h1,IF(A3<=12,d_h2,in_churn_late)) | C3: =C2*(1-B2) | D3: =C2-C3
A4: 3 | B4: =IF(A4<=3,d_h1,IF(A4<=12,d_h2,in_churn_late)) | C4: =C3*(1-B3) | D4: =C3-C4
A5: 4 | B5: =IF(A5<=3,d_h1,IF(A5<=12,d_h2,in_churn_late)) | C5: =C4*(1-B4) | D5: =C4-C5
A6: 5 | B6: =IF(A6<=3,d_h1,IF(A6<=12,d_h2,in_churn_late)) | C6: =C5*(1-B5) | D6: =C5-C6
A7: 6 | B7: =IF(A7<=3,d_h1,IF(A7<=12,d_h2,in_churn_late)) | C7: =C6*(1-B6) | D7: =C6-C7
A8: 7 | B8: =IF(A8<=3,d_h1,IF(A8<=12,d_h2,in_churn_late)) | C8: =C7*(1-B7) | D8: =C7-C8
A9: 8 | B9: =IF(A9<=3,d_h1,IF(A9<=12,d_h2,in_churn_late)) | C9: =C8*(1-B8) | D9: =C8-C9
A10: 9 | B10: =IF(A10<=3,d_h1,IF(A10<=12,d_h2,in_churn_late)) | C10: =C9*(1-B9) | D10: =C9-C10
A11: 10 | B11: =IF(A11<=3,d_h1,IF(A11<=12,d_h2,in_churn_late)) | C11: =C10*(1-B10) | D11: =C10-C11
A12: 11 | B12: =IF(A12<=3,d_h1,IF(A12<=12,d_h2,in_churn_late)) | C12: =C11*(1-B11) | D12: =C11-C12
A13: 12 | B13: =IF(A13<=3,d_h1,IF(A13<=12,d_h2,in_churn_late)) | C13: =C12*(1-B12) | D13: =C12-C13
A14: 13 | B14: =IF(A14<=3,d_h1,IF(A14<=12,d_h2,in_churn_late)) | C14: =C13*(1-B13) | D14: =C13-C14
... A61: 60 | B61: =IF(A61<=3,d_h1,IF(A61<=12,d_h2,in_churn_late)) | C61: =C60*(1-B60) | D61: =C60-C61
A63: Months 1-3 drop at d_h1 (so month 4 = r3), months 4-12 at d_h2 (so month 13 = r12), then churn_late. 'Still saving at month m' = survived m monthly drop-offs (the v2 convention).

Sheet Age profile
A1: Age (month since sign-up) | B1: Still saving | C1: Stopped this month | D1: Deposit per active saver (Rs) | E1: Deposits (Rs) | F1: Balance at the month's start, per active saver (Rs) | G1: Balance at the month's end, per active saver, with his return (Rs) | H1: Average balance in the fund (Rs) | I1: Withdrawn this month (Rs) | J1: Share on UPI | K1: Cash savers | L1: Cash visits a day | M1: Savers offered the marketplace (still saving) | N1: Early take-up factor | O1: Early approval factor | P1: Card window: early factors in the first card months (helper) | Q1: Fund commission (Rs) | R1: KYC cost (Rs) | S1: Support cost (Rs) | T1: Discount factor at his age | U1: Fund commission less KYC and support, discounted to his sign-up month (Rs)
A2: 1 | B2: ='Retention curve'!C2 | C2: ='Retention curve'!D2 | D2: =in_daily*in_days*(1+in_amount_growth)^INT((A2-1)/in_term) | E2: =B2*D2 | F2: =IF(A2=1,0,G1*IF(MOD(A2-1,in_term)=0,in_rollover,1)) | G2: =F2*(1-in_withdraw_m)+D2+(F2*(1-in_withdraw_m)+0.5*D2)*d_rm | H2: =B2*(F2*(1-in_withdraw_m)+0.5*D2) | I2: =B2*in_withdraw_m*F2+IF(A2=1,0,C2*G1+IF(MOD(A2-1,in_term)=0,B2*(1-in_rollover)*G1,0)) | J2: =in_upi_12*MIN(1,(A2-1)/(in_upi_ramp-1)) | K2: =B2*(1-J2) | L2: =K2/in_visit_every | M2: =IF(A2>=in_marketplace_from,B2,0) | N2: =IF(A2<=in_early_months,in_early_takeup_mult,1) | O2: =IF(A2<=in_early_months,in_early_approval_mult,1) | P2: =IF(AND(A2>=in_marketplace_from,A2<in_marketplace_from+in_card_months),N2*O2,0) | Q2: =H2*in_trail/12 | R2: =IF(A2=1,in_kyc_cost,0) | S2: =B2*in_support_cost | T2: =1/(1+d_dm)^(A2-1) | U2: =(Q2-R2-S2)*T2
A3: 2 | B3: ='Retention curve'!C3 | C3: ='Retention curve'!D3 | D3: =in_daily*in_days*(1+in_amount_growth)^INT((A3-1)/in_term) | E3: =B3*D3 | F3: =IF(A3=1,0,G2*IF(MOD(A3-1,in_term)=0,in_rollover,1)) | G3: =F3*(1-in_withdraw_m)+D3+(F3*(1-in_withdraw_m)+0.5*D3)*d_rm | H3: =B3*(F3*(1-in_withdraw_m)+0.5*D3) | I3: =B3*in_withdraw_m*F3+IF(A3=1,0,C3*G2+IF(MOD(A3-1,in_term)=0,B3*(1-in_rollover)*G2,0)) | J3: =in_upi_12*MIN(1,(A3-1)/(in_upi_ramp-1)) | K3: =B3*(1-J3) | L3: =K3/in_visit_every | M3: =IF(A3>=in_marketplace_from,B3,0) | N3: =IF(A3<=in_early_months,in_early_takeup_mult,1) | O3: =IF(A3<=in_early_months,in_early_approval_mult,1) | P3: =IF(AND(A3>=in_marketplace_from,A3<in_marketplace_from+in_card_months),N3*O3,0) | Q3: =H3*in_trail/12 | R3: =IF(A3=1,in_kyc_cost,0) | S3: =B3*in_support_cost | T3: =1/(1+d_dm)^(A3-1) | U3: =(Q3-R3-S3)*T3
A4: 3 | B4: ='Retention curve'!C4 | C4: ='Retention curve'!D4 | D4: =in_daily*in_days*(1+in_amount_growth)^INT((A4-1)/in_term) | E4: =B4*D4 | F4: =IF(A4=1,0,G3*IF(MOD(A4-1,in_term)=0,in_rollover,1)) | G4: =F4*(1-in_withdraw_m)+D4+(F4*(1-in_withdraw_m)+0.5*D4)*d_rm | H4: =B4*(F4*(1-in_withdraw_m)+0.5*D4) | I4: =B4*in_withdraw_m*F4+IF(A4=1,0,C4*G3+IF(MOD(A4-1,in_term)=0,B4*(1-in_rollover)*G3,0)) | J4: =in_upi_12*MIN(1,(A4-1)/(in_upi_ramp-1)) | K4: =B4*(1-J4) | L4: =K4/in_visit_every | M4: =IF(A4>=in_marketplace_from,B4,0) | N4: =IF(A4<=in_early_months,in_early_takeup_mult,1) | O4: =IF(A4<=in_early_months,in_early_approval_mult,1) | P4: =IF(AND(A4>=in_marketplace_from,A4<in_marketplace_from+in_card_months),N4*O4,0) | Q4: =H4*in_trail/12 | R4: =IF(A4=1,in_kyc_cost,0) | S4: =B4*in_support_cost | T4: =1/(1+d_dm)^(A4-1) | U4: =(Q4-R4-S4)*T4
A5: 4 | B5: ='Retention curve'!C5 | C5: ='Retention curve'!D5 | D5: =in_daily*in_days*(1+in_amount_growth)^INT((A5-1)/in_term) | E5: =B5*D5 | F5: =IF(A5=1,0,G4*IF(MOD(A5-1,in_term)=0,in_rollover,1)) | G5: =F5*(1-in_withdraw_m)+D5+(F5*(1-in_withdraw_m)+0.5*D5)*d_rm | H5: =B5*(F5*(1-in_withdraw_m)+0.5*D5) | I5: =B5*in_withdraw_m*F5+IF(A5=1,0,C5*G4+IF(MOD(A5-1,in_term)=0,B5*(1-in_rollover)*G4,0)) | J5: =in_upi_12*MIN(1,(A5-1)/(in_upi_ramp-1)) | K5: =B5*(1-J5) | L5: =K5/in_visit_every | M5: =IF(A5>=in_marketplace_from,B5,0) | N5: =IF(A5<=in_early_months,in_early_takeup_mult,1) | O5: =IF(A5<=in_early_months,in_early_approval_mult,1) | P5: =IF(AND(A5>=in_marketplace_from,A5<in_marketplace_from+in_card_months),N5*O5,0) | Q5: =H5*in_trail/12 | R5: =IF(A5=1,in_kyc_cost,0) | S5: =B5*in_support_cost | T5: =1/(1+d_dm)^(A5-1) | U5: =(Q5-R5-S5)*T5
A6: 5 | B6: ='Retention curve'!C6 | C6: ='Retention curve'!D6 | D6: =in_daily*in_days*(1+in_amount_growth)^INT((A6-1)/in_term) | E6: =B6*D6 | F6: =IF(A6=1,0,G5*IF(MOD(A6-1,in_term)=0,in_rollover,1)) | G6: =F6*(1-in_withdraw_m)+D6+(F6*(1-in_withdraw_m)+0.5*D6)*d_rm | H6: =B6*(F6*(1-in_withdraw_m)+0.5*D6) | I6: =B6*in_withdraw_m*F6+IF(A6=1,0,C6*G5+IF(MOD(A6-1,in_term)=0,B6*(1-in_rollover)*G5,0)) | J6: =in_upi_12*MIN(1,(A6-1)/(in_upi_ramp-1)) | K6: =B6*(1-J6) | L6: =K6/in_visit_every | M6: =IF(A6>=in_marketplace_from,B6,0) | N6: =IF(A6<=in_early_months,in_early_takeup_mult,1) | O6: =IF(A6<=in_early_months,in_early_approval_mult,1) | P6: =IF(AND(A6>=in_marketplace_from,A6<in_marketplace_from+in_card_months),N6*O6,0) | Q6: =H6*in_trail/12 | R6: =IF(A6=1,in_kyc_cost,0) | S6: =B6*in_support_cost | T6: =1/(1+d_dm)^(A6-1) | U6: =(Q6-R6-S6)*T6
A7: 6 | B7: ='Retention curve'!C7 | C7: ='Retention curve'!D7 | D7: =in_daily*in_days*(1+in_amount_growth)^INT((A7-1)/in_term) | E7: =B7*D7 | F7: =IF(A7=1,0,G6*IF(MOD(A7-1,in_term)=0,in_rollover,1)) | G7: =F7*(1-in_withdraw_m)+D7+(F7*(1-in_withdraw_m)+0.5*D7)*d_rm | H7: =B7*(F7*(1-in_withdraw_m)+0.5*D7) | I7: =B7*in_withdraw_m*F7+IF(A7=1,0,C7*G6+IF(MOD(A7-1,in_term)=0,B7*(1-in_rollover)*G6,0)) | J7: =in_upi_12*MIN(1,(A7-1)/(in_upi_ramp-1)) | K7: =B7*(1-J7) | L7: =K7/in_visit_every | M7: =IF(A7>=in_marketplace_from,B7,0) | N7: =IF(A7<=in_early_months,in_early_takeup_mult,1) | O7: =IF(A7<=in_early_months,in_early_approval_mult,1) | P7: =IF(AND(A7>=in_marketplace_from,A7<in_marketplace_from+in_card_months),N7*O7,0) | Q7: =H7*in_trail/12 | R7: =IF(A7=1,in_kyc_cost,0) | S7: =B7*in_support_cost | T7: =1/(1+d_dm)^(A7-1) | U7: =(Q7-R7-S7)*T7
A8: 7 | B8: ='Retention curve'!C8 | C8: ='Retention curve'!D8 | D8: =in_daily*in_days*(1+in_amount_growth)^INT((A8-1)/in_term) | E8: =B8*D8 | F8: =IF(A8=1,0,G7*IF(MOD(A8-1,in_term)=0,in_rollover,1)) | G8: =F8*(1-in_withdraw_m)+D8+(F8*(1-in_withdraw_m)+0.5*D8)*d_rm | H8: =B8*(F8*(1-in_withdraw_m)+0.5*D8) | I8: =B8*in_withdraw_m*F8+IF(A8=1,0,C8*G7+IF(MOD(A8-1,in_term)=0,B8*(1-in_rollover)*G7,0)) | J8: =in_upi_12*MIN(1,(A8-1)/(in_upi_ramp-1)) | K8: =B8*(1-J8) | L8: =K8/in_visit_every | M8: =IF(A8>=in_marketplace_from,B8,0) | N8: =IF(A8<=in_early_months,in_early_takeup_mult,1) | O8: =IF(A8<=in_early_months,in_early_approval_mult,1) | P8: =IF(AND(A8>=in_marketplace_from,A8<in_marketplace_from+in_card_months),N8*O8,0) | Q8: =H8*in_trail/12 | R8: =IF(A8=1,in_kyc_cost,0) | S8: =B8*in_support_cost | T8: =1/(1+d_dm)^(A8-1) | U8: =(Q8-R8-S8)*T8
A9: 8 | B9: ='Retention curve'!C9 | C9: ='Retention curve'!D9 | D9: =in_daily*in_days*(1+in_amount_growth)^INT((A9-1)/in_term) | E9: =B9*D9 | F9: =IF(A9=1,0,G8*IF(MOD(A9-1,in_term)=0,in_rollover,1)) | G9: =F9*(1-in_withdraw_m)+D9+(F9*(1-in_withdraw_m)+0.5*D9)*d_rm | H9: =B9*(F9*(1-in_withdraw_m)+0.5*D9) | I9: =B9*in_withdraw_m*F9+IF(A9=1,0,C9*G8+IF(MOD(A9-1,in_term)=0,B9*(1-in_rollover)*G8,0)) | J9: =in_upi_12*MIN(1,(A9-1)/(in_upi_ramp-1)) | K9: =B9*(1-J9) | L9: =K9/in_visit_every | M9: =IF(A9>=in_marketplace_from,B9,0) | N9: =IF(A9<=in_early_months,in_early_takeup_mult,1) | O9: =IF(A9<=in_early_months,in_early_approval_mult,1) | P9: =IF(AND(A9>=in_marketplace_from,A9<in_marketplace_from+in_card_months),N9*O9,0) | Q9: =H9*in_trail/12 | R9: =IF(A9=1,in_kyc_cost,0) | S9: =B9*in_support_cost | T9: =1/(1+d_dm)^(A9-1) | U9: =(Q9-R9-S9)*T9
A10: 9 | B10: ='Retention curve'!C10 | C10: ='Retention curve'!D10 | D10: =in_daily*in_days*(1+in_amount_growth)^INT((A10-1)/in_term) | E10: =B10*D10 | F10: =IF(A10=1,0,G9*IF(MOD(A10-1,in_term)=0,in_rollover,1)) | G10: =F10*(1-in_withdraw_m)+D10+(F10*(1-in_withdraw_m)+0.5*D10)*d_rm | H10: =B10*(F10*(1-in_withdraw_m)+0.5*D10) | I10: =B10*in_withdraw_m*F10+IF(A10=1,0,C10*G9+IF(MOD(A10-1,in_term)=0,B10*(1-in_rollover)*G9,0)) | J10: =in_upi_12*MIN(1,(A10-1)/(in_upi_ramp-1)) | K10: =B10*(1-J10) | L10: =K10/in_visit_every | M10: =IF(A10>=in_marketplace_from,B10,0) | N10: =IF(A10<=in_early_months,in_early_takeup_mult,1) | O10: =IF(A10<=in_early_months,in_early_approval_mult,1) | P10: =IF(AND(A10>=in_marketplace_from,A10<in_marketplace_from+in_card_months),N10*O10,0) | Q10: =H10*in_trail/12 | R10: =IF(A10=1,in_kyc_cost,0) | S10: =B10*in_support_cost | T10: =1/(1+d_dm)^(A10-1) | U10: =(Q10-R10-S10)*T10
A11: 10 | B11: ='Retention curve'!C11 | C11: ='Retention curve'!D11 | D11: =in_daily*in_days*(1+in_amount_growth)^INT((A11-1)/in_term) | E11: =B11*D11 | F11: =IF(A11=1,0,G10*IF(MOD(A11-1,in_term)=0,in_rollover,1)) | G11: =F11*(1-in_withdraw_m)+D11+(F11*(1-in_withdraw_m)+0.5*D11)*d_rm | H11: =B11*(F11*(1-in_withdraw_m)+0.5*D11) | I11: =B11*in_withdraw_m*F11+IF(A11=1,0,C11*G10+IF(MOD(A11-1,in_term)=0,B11*(1-in_rollover)*G10,0)) | J11: =in_upi_12*MIN(1,(A11-1)/(in_upi_ramp-1)) | K11: =B11*(1-J11) | L11: =K11/in_visit_every | M11: =IF(A11>=in_marketplace_from,B11,0) | N11: =IF(A11<=in_early_months,in_early_takeup_mult,1) | O11: =IF(A11<=in_early_months,in_early_approval_mult,1) | P11: =IF(AND(A11>=in_marketplace_from,A11<in_marketplace_from+in_card_months),N11*O11,0) | Q11: =H11*in_trail/12 | R11: =IF(A11=1,in_kyc_cost,0) | S11: =B11*in_support_cost | T11: =1/(1+d_dm)^(A11-1) | U11: =(Q11-R11-S11)*T11
A12: 11 | B12: ='Retention curve'!C12 | C12: ='Retention curve'!D12 | D12: =in_daily*in_days*(1+in_amount_growth)^INT((A12-1)/in_term) | E12: =B12*D12 | F12: =IF(A12=1,0,G11*IF(MOD(A12-1,in_term)=0,in_rollover,1)) | G12: =F12*(1-in_withdraw_m)+D12+(F12*(1-in_withdraw_m)+0.5*D12)*d_rm | H12: =B12*(F12*(1-in_withdraw_m)+0.5*D12) | I12: =B12*in_withdraw_m*F12+IF(A12=1,0,C12*G11+IF(MOD(A12-1,in_term)=0,B12*(1-in_rollover)*G11,0)) | J12: =in_upi_12*MIN(1,(A12-1)/(in_upi_ramp-1)) | K12: =B12*(1-J12) | L12: =K12/in_visit_every | M12: =IF(A12>=in_marketplace_from,B12,0) | N12: =IF(A12<=in_early_months,in_early_takeup_mult,1) | O12: =IF(A12<=in_early_months,in_early_approval_mult,1) | P12: =IF(AND(A12>=in_marketplace_from,A12<in_marketplace_from+in_card_months),N12*O12,0) | Q12: =H12*in_trail/12 | R12: =IF(A12=1,in_kyc_cost,0) | S12: =B12*in_support_cost | T12: =1/(1+d_dm)^(A12-1) | U12: =(Q12-R12-S12)*T12
A13: 12 | B13: ='Retention curve'!C13 | C13: ='Retention curve'!D13 | D13: =in_daily*in_days*(1+in_amount_growth)^INT((A13-1)/in_term) | E13: =B13*D13 | F13: =IF(A13=1,0,G12*IF(MOD(A13-1,in_term)=0,in_rollover,1)) | G13: =F13*(1-in_withdraw_m)+D13+(F13*(1-in_withdraw_m)+0.5*D13)*d_rm | H13: =B13*(F13*(1-in_withdraw_m)+0.5*D13) | I13: =B13*in_withdraw_m*F13+IF(A13=1,0,C13*G12+IF(MOD(A13-1,in_term)=0,B13*(1-in_rollover)*G12,0)) | J13: =in_upi_12*MIN(1,(A13-1)/(in_upi_ramp-1)) | K13: =B13*(1-J13) | L13: =K13/in_visit_every | M13: =IF(A13>=in_marketplace_from,B13,0) | N13: =IF(A13<=in_early_months,in_early_takeup_mult,1) | O13: =IF(A13<=in_early_months,in_early_approval_mult,1) | P13: =IF(AND(A13>=in_marketplace_from,A13<in_marketplace_from+in_card_months),N13*O13,0) | Q13: =H13*in_trail/12 | R13: =IF(A13=1,in_kyc_cost,0) | S13: =B13*in_support_cost | T13: =1/(1+d_dm)^(A13-1) | U13: =(Q13-R13-S13)*T13
... A61: 60 | B61: ='Retention curve'!C61 | C61: ='Retention curve'!D61 | D61: =in_daily*in_days*(1+in_amount_growth)^INT((A61-1)/in_term) | E61: =B61*D61 | F61: =IF(A61=1,0,G60*IF(MOD(A61-1,in_term)=0,in_rollover,1)) | G61: =F61*(1-in_withdraw_m)+D61+(F61*(1-in_withdraw_m)+0.5*D61)*d_rm | H61: =B61*(F61*(1-in_withdraw_m)+0.5*D61) | I61: =B61*in_withdraw_m*F61+IF(A61=1,0,C61*G60+IF(MOD(A61-1,in_term)=0,B61*(1-in_rollover)*G60,0)) | J61: =in_upi_12*MIN(1,(A61-1)/(in_upi_ramp-1)) | K61: =B61*(1-J61) | L61: =K61/in_visit_every | M61: =IF(A61>=in_marketplace_from,B61,0) | N61: =IF(A61<=in_early_months,in_early_takeup_mult,1) | O61: =IF(A61<=in_early_months,in_early_approval_mult,1) | P61: =IF(AND(A61>=in_marketplace_from,A61<in_marketplace_from+in_card_months),N61*O61,0) | Q61: =H61*in_trail/12 | R61: =IF(A61=1,in_kyc_cost,0) | S61: =B61*in_support_cost | T61: =1/(1+d_dm)^(A61-1) | U61: =(Q61-R61-S61)*T61
A63: Per sign-up. The marketplace lines (loans, top-ups, cards, the 17 products, collections) depend on the calendar year as well as his age, because take-up and approvals grow with the pool's history: they are on 'Cohort x age'.

Sheet Cohort x age
A1: Sign-up month (cohort) | B1: Age | C1: Calendar month | D1: Calendar year | E1: Cohort's sign-ups | F1: Still saving | G1: Take-up factor (early months x pool history, cap) | H1: First-loan approval (cap 80%) | I1: Card factor (take-up x approval) | J1: No loan yet | K1: Repaid a loan, can apply for a repeat | L1: First loans | M1: Repeat loans | N1: Loans made | O1: Loans per active saver (helper) | P1: Savers with a loan running | Q1: Loan applications | R1: Loans with an EMI due | S1: Top-up window (helper) | T1: Top-ups | U1: Money lent, first and repeat loans (Rs) | V1: Money lent, with top-ups (Rs) | W1: Loans for collections (top-ups pro rata) | X1: Overdue accounts brought back, 31-90 days | Y1: Overdue accounts recovered, 90+ | Z1: Cards issued (the share held back by the early factors follows in the next 6 months) | AA1: Origination fees net of taken back (Rs) | AB1: 31-90 day collection fees (Rs) | AC1: 90+ recovery fees (Rs) | AD1: Card fees (Rs) | AE1: Small health / hospital cash: never held it (share of active savers) | AF1: Small health / hospital cash: take-ups per active saver | AG1: Small health / hospital cash (Rs) | AH1: Family health cover: never held it (share of active savers) | AI1: Family health cover: take-ups per active saver | AJ1: Family health cover (Rs) | AK1: Term life (small cover): never held it (share of active savers) | AL1: Term life (small cover): take-ups per active saver | AM1: Term life (small cover) (Rs) | AN1: Personal accident: never held it (share of active savers) | AO1: Personal accident: take-ups per active saver | AP1: Personal accident (Rs) | AQ1: Two-wheeler insurance: never held it (share of active savers) | AR1: Two-wheeler insurance: take-ups per active saver | AS1: Two-wheeler insurance (Rs) | AT1: Mobile / device insurance: never held it (share of active savers) | AU1: Mobile / device insurance (Rs) | AV1: Shop insurance (fire and burglary): never held it (share of active savers) | AW1: Shop insurance (fire and burglary): take-ups per active saver | AX1: Shop insurance (fire and burglary) (Rs) | AY1: Equity/hybrid SIP trail: never held it (share of active savers) | AZ1: Equity/hybrid SIP trail: holders per active saver | BA1: Equity/hybrid SIP trail: SIP months held per active saver (helper) | BB1: Equity/hybrid SIP trail (Rs) | BC1: Choti SIP incentive: never held it (share of active savers) | BD1: Choti SIP incentive: take-ups per active saver | BE1: Choti SIP incentive (Rs) | BF1: NPS: never held it (share of active savers) | BG1: NPS (Rs) | BH1: Digital gold: never held it (share of active savers) | BI1: Digital gold: holders per active saver | BJ1: Digital gold (Rs) | BK1: FD via partner banks: never held it (share of active savers) | BL1: FD via partner banks (Rs) | BM1: Mobile recharge: never held it (share of active savers) | BN1: Mobile recharge: holders per active saver | BO1: Mobile recharge (Rs) | BP1: Bill payments: never held it (share of active savers) | BQ1: Bill payments: holders per active saver | BR1: Bill payments (Rs) | BS1: Gold loan (other lenders): never held it (share of active savers) | BT1: Gold loan (other lenders) (Rs) | BU1: Consumer-durable loan: never held it (share of active savers) | BV1: Consumer-durable loan (Rs) | BW1: Two-wheeler / e-rickshaw loan: never held it (share of active savers) | BX1: Two-wheeler / e-rickshaw loan (Rs) | BY1: Home loan (affordable housing): never had one (share of active savers) | BZ1: Home loan (affordable housing): approval (cap 80%) | CA1: Home loan (affordable housing) (Rs) | CB1: Loan against property (shop or home): never had one (share of active savers) | CC1: Loan against property (shop or home): approval (cap 80%) | CD1: Loan against property (shop or home) (Rs) | CE1: Marketplace income (Rs)
A2: 1 | B2: 1 | C2: =A2+B2-1 | D2: =INT((C2-1)/12)+1 | E2: =INDEX(Monthly!$B$2:$B$61,A2) | F2: =E2*INDEX('Age profile'!$B$2:$B$61,B2) | G2: =MIN(in_takeup_cap,INDEX('Age profile'!$N$2:$N$61,B2)*(1+in_takeup_growth)^(D2-1)) | H2: =MIN(in_approval_cap,in_approved_first*INDEX('Age profile'!$O$2:$O$61,B2)*(1+in_approval_growth)^(D2-1)) | I2: =G2*MIN(in_takeup_cap,INDEX('Age profile'!$O$2:$O$61,B2)*(1+in_approval_growth)^(D2-1)) | J2: =E2 | K2: 0 | L2: =IF(B2>=in_marketplace_from,J2*d_hz*G2*in_eligible*H2,0) | M2: =IF(B2>=in_marketplace_from,K2*d_hz*G2*in_eligible*in_approved_repeat,0) | N2: =L2+M2 | O2: =N2/F2 | P2: =F2-J2-K2 | Q2: =IF(B2>=in_marketplace_from,(J2+K2)*d_hz*G2,0) | R2: =SUMIFS(N2:N61,B2:B61,">="&(B2-d_T),B2:B61,"<="&(B2-1)) | S2: 0 | T2: =F2*d_u*S2 | U2: =L2*in_ticket+M2*d_rep_ticket | V2: =U2+T2*d_topup_amt | W2: =N2+T2*d_topup_ratio | X2: =SUMIFS(W2:W61,B2:B61,B2-in_dpd_lag)*d_cured | Y2: =SUMIFS(W2:W61,B2:B61,B2-in_rec_lag)*d_recd | Z2: =IF(AND(B2>=in_marketplace_from,B2<in_marketplace_from+in_card_months),in_card_share/in_card_months*F2*I2,IF(AND(B2>=in_marketplace_from+in_card_months,B2<in_marketplace_from+2*in_card_months),in_card_share*d_card_rem/in_card_months*F2*MIN(in_takeup_cap,(1+in_takeup_growth)^(D2-1))*MIN(in_takeup_cap,(1+in_approval_growth)^(D2-1)),0)) | AA2: =V2*in_fee*(1-in_taken_back) | AB2: =SUMIFS(W2:W61,B2:B61,B2-in_dpd_lag)*d_dpd | AC2: =SUMIFS(W2:W61,B2:B61,B2-in_rec_lag)*d_rec | AD2: =Z2*in_card_fee | AE2: 1 | AF2: =AE2*IF(B2>=in_marketplace_from,d_hz_hlth_small*G2,0) | AG2: =F2*AF2*in_hlth_small_ticket*in_hlth_small_comm*in_ins_partner_share+F2*in_hlth_small_ticket*in_hlth_small_renew_comm*in_ins_partner_share*(in_hlth_small_renew^1*SUMIFS(AF2:AF61,B2:B61,B2-12)+in_hlth_small_renew^2*SUMIFS(AF2:AF61,B2:B61,B2-24)+in_hlth_small_renew^3*SUMIFS(AF2:AF61,B2:B61,B2-36)+in_hlth_small_renew^4*SUMIFS(AF2:AF61,B2:B61,B2-48)) | AH2: 1 | AI2: =AH2*IF(B2>=in_marketplace_from,d_hz_hlth_family*G2,0) | AJ2: =F2*AI2*in_hlth_family_ticket*in_hlth_family_comm*in_ins_partner_share+F2*in_hlth_family_ticket*in_hlth_family_renew_comm*in_ins_partner_share*(in_hlth_family_renew^1*SUMIFS(AI2:AI61,B2:B61,B2-12)+in_hlth_family_renew^2*SUMIFS(AI2:AI61,B2:B61,B2-24)+in_hlth_family_renew^3*SUMIFS(AI2:AI61,B2:B61,B2-36)+in_hlth_family_renew^4*SUMIFS(AI2:AI61,B2:B61,B2-48)) | AK2: 1 | AL2: =AK2*IF(B2>=in_marketplace_from,d_hz_life_term*G2,0) | AM2: =F2*AL2*in_life_term_ticket*in_life_term_comm*in_ins_partner_share+F2*in_life_term_ticket*in_life_term_renew_comm*in_ins_partner_share*(in_life_term_renew^1*SUMIFS(AL2:AL61,B2:B61,B2-12)+in_life_term_renew^2*SUMIFS(AL2:AL61,B2:B61,B2-24)+in_life_term_renew^3*SUMIFS(AL2:AL61,B2:B61,B2-36)+in_life_term_renew^4*SUMIFS(AL2:AL61,B2:B61,B2-48)) | AN2: 1 | AO2: =AN2*IF(B2>=in_marketplace_from,d_hz_accident*G2,0) | AP2: =F2*AO2*in_accident_ticket*in_accident_comm*in_ins_partner_share+F2*in_accident_ticket*in_accident_renew_comm*in_ins_partner_share*(in_accident_renew^1*SUMIFS(AO2:AO61,B2:B61,B2-12)+in_accident_renew^2*SUMIFS(AO2:AO61,B2:B61,B2-24)+in_accident_renew^3*SUMIFS(AO2:AO61,B2:B61,B2-36)+in_accident_renew^4*SUMIFS(AO2:AO61,B2:B61,B2-48)) | AQ2: 1 | AR2: =AQ2*IF(B2>=in_marketplace_from,d_hz_two_wheeler*G2,0) | AS2: =F2*AR2*in_two_wheeler_ticket*in_two_wheeler_comm*in_ins_partner_share+F2*in_two_wheeler_ticket*in_two_wheeler_comm*in_ins_partner_share*(in_two_wheeler_renew^1*SUMIFS(AR2:AR61,B2:B61,B2-12)+in_two_wheeler_renew^2*SUMIFS(AR2:AR61,B2:B61,B2-24)+in_two_wheeler_renew^3*SUMIFS(AR2:AR61,B2:B61,B2-36)+in_two_wheeler_renew^4*SUMIFS(AR2:AR61,B2:B61,B2-48)) | AT2: 1 | AU2: =F2*AT2*IF(B2>=in_marketplace_from,d_hz_device*G2,0)*in_device_ticket*in_device_comm*in_ins_partner_share | AV2: 1 | AW2: =AV2*IF(B2>=in_marketplace_from,d_hz_shop*G2,0) | AX2: =F2*AW2*in_shop_ticket*in_shop_comm*in_ins_partner_share+F2*in_shop_ticket*in_shop_renew_comm*in_ins_partner_share*(in_shop_renew^1*SUMIFS(AW2:AW61,B2:B61,B2-12)+in_shop_renew^2*SUMIFS(AW2:AW61,B2:B61,B2-24)+in_shop_renew^3*SUMIFS(AW2:AW61,B2:B61,B2-36)+in_shop_renew^4*SUMIFS(AW2:AW61,B2:B61,B2-48)) | AY2: 1 | AZ2: =AY2*IF(B2>=in_marketplace_from,d_hz_sip*G2,0) | BA2: 0 | BB2: =F2*in_sip_ticket*(BA2+0.5*AZ2)*in_sip_comm/12 | BC2: 1 | BD2: =BC2*IF(B2>=in_marketplace_from,d_hz_choti*G2,0) | BE2: =F2*SUMIFS(BD2:BD61,B2:B61,B2-in_choti_months)*in_choti_renew*in_choti_ticket | BF2: 1 | BG2: =F2*BF2*IF(B2>=in_marketplace_from,d_hz_nps*G2,0)*in_nps_ticket*in_nps_comm | BH2: 1 | BI2: =BH2*IF(B2>=in_marketplace_from,d_hz_gold*G2,0) | BJ2: =F2*BI2*in_gold_ticket*in_gold_comm | BK2: 1 | BL2: =F2*BK2*IF(B2>=in_marketplace_from,d_hz_fd*G2,0)*in_fd_ticket*in_fd_comm | BM2: 1 | BN2: =BM2*IF(B2>=in_marketplace_from,d_hz_recharge*G2,0) | BO2: =F2*BN2*in_recharge_ticket*in_recharge_comm/12 | BP2: 1 | BQ2: =BP2*IF(B2>=in_marketplace_from,d_hz_bills*G2,0) | BR2: =F2*BQ2*in_bills_ticket*in_bills_comm/12 | BS2: 1 | BT2: =F2*BS2*IF(B2>=in_marketplace_from,d_hz_loan_gold*G2,0)*in_loan_gold_ticket*in_loan_gold_comm | BU2: 1 | BV2: =F2*BU2*IF(B2>=in_marketplace_from,d_hz_loan_cd*G2,0)*in_loan_cd_ticket*in_loan_cd_comm | BW2: 1 | BX2: =F2*BW2*IF(B2>=in_marketplace_from,d_hz_loan_vehicle*G2,0)*in_loan_vehicle_ticket*in_loan_vehicle_comm | BY2: 1 | BZ2: =MIN(in_approval_cap,in_loan_home_approval*INDEX('Age profile'!$O$2:$O$61,B2)*(1+in_approval_growth)^(D2-1)) | CA2: =F2*BY2*IF(B2>=in_marketplace_from,d_hz_loan_home*G2,0)*BZ2*in_loan_home_ticket*in_loan_home_comm | CB2: 1 | CC2: =MIN(in_approval_cap,in_loan_lap_approval*INDEX('Age profile'!$O$2:$O$61,B2)*(1+in_approval_growth)^(D2-1)) | CD2: =F2*CB2*IF(B2>=in_marketplace_from,d_hz_loan_lap*G2,0)*CC2*in_loan_lap_ticket*in_loan_lap_comm | CE2: =AA2+AB2+AC2+AD2+AG2+AJ2+AM2+AP2+AS2+AU2+AX2+BB2+BE2+BG2+BJ2+BL2+BO2+BR2+BT2+BV2+BX2+CA2+CD2
A3: 1 | B3: 2 | C3: =A3+B3-1 | D3: =INT((C3-1)/12)+1 | E3: =INDEX(Monthly!$B$2:$B$61,A3) | F3: =E3*INDEX('Age profile'!$B$2:$B$61,B3) | G3: =MIN(in_takeup_cap,INDEX('Age profile'!$N$2:$N$61,B3)*(1+in_takeup_growth)^(D3-1)) | H3: =MIN(in_approval_cap,in_approved_first*INDEX('Age profile'!$O$2:$O$61,B3)*(1+in_approval_growth)^(D3-1)) | I3: =G3*MIN(in_takeup_cap,INDEX('Age profile'!$O$2:$O$61,B3)*(1+in_approval_growth)^(D3-1)) | J3: =(J2-L2)*F3/F2 | K3: =(K2-M2)*F3/F2+SUMIFS(O2:O2,B2:B2,B3-1-d_T)*F3 | L3: =IF(B3>=in_marketplace_from,J3*d_hz*G3*in_eligible*H3,0) | M3: =IF(B3>=in_marketplace_from,K3*d_hz*G3*in_eligible*in_approved_repeat,0) | N3: =L3+M3 | O3: =N3/F3 | P3: =F3-J3-K3 | Q3: =IF(B3>=in_marketplace_from,(J3+K3)*d_hz*G3,0) | R3: =SUMIFS(N2:N61,B2:B61,">="&(B3-d_T),B2:B61,"<="&(B3-1)) | S3: =(1-d_u)*S2+IF(d_T>in_topup_lag,SUMIFS(O2:O61,B2:B61,B3-in_topup_lag)-d_udrop*SUMIFS(O2:O61,B2:B61,B3-d_T),0) | T3: =F3*d_u*S3 | U3: =L3*in_ticket+M3*d_rep_ticket | V3: =U3+T3*d_topup_amt | W3: =N3+T3*d_topup_ratio | X3: =SUMIFS(W2:W61,B2:B61,B3-in_dpd_lag)*d_cured | Y3: =SUMIFS(W2:W61,B2:B61,B3-in_rec_lag)*d_recd | Z3: =IF(AND(B3>=in_marketplace_from,B3<in_marketplace_from+in_card_months),in_card_share/in_card_months*F3*I3,IF(AND(B3>=in_marketplace_from+in_card_months,B3<in_marketplace_from+2*in_card_months),in_card_share*d_card_rem/in_card_months*F3*MIN(in_takeup_cap,(1+in_takeup_growth)^(D3-1))*MIN(in_takeup_cap,(1+in_approval_growth)^(D3-1)),0)) | AA3: =V3*in_fee*(1-in_taken_back) | AB3: =SUMIFS(W2:W61,B2:B61,B3-in_dpd_lag)*d_dpd | AC3: =SUMIFS(W2:W61,B2:B61,B3-in_rec_lag)*d_rec | AD3: =Z3*in_card_fee | AE3: =AE2*(1-IF(B2>=in_marketplace_from,d_hz_hlth_small*G2,0)) | AF3: =AE3*IF(B3>=in_marketplace_from,d_hz_hlth_small*G3,0) | AG3: =F3*AF3*in_hlth_small_ticket*in_hlth_small_comm*in_ins_partner_share+F3*in_hlth_small_ticket*in_hlth_small_renew_comm*in_ins_partner_share*(in_hlth_small_renew^1*SUMIFS(AF2:AF61,B2:B61,B3-12)+in_hlth_small_renew^2*SUMIFS(AF2:AF61,B2:B61,B3-24)+in_hlth_small_renew^3*SUMIFS(AF2:AF61,B2:B61,B3-36)+in_hlth_small_renew^4*SUMIFS(AF2:AF61,B2:B61,B3-48)) | AH3: =AH2*(1-IF(B2>=in_marketplace_from,d_hz_hlth_family*G2,0)) | AI3: =AH3*IF(B3>=in_marketplace_from,d_hz_hlth_family*G3,0) | AJ3: =F3*AI3*in_hlth_family_ticket*in_hlth_family_comm*in_ins_partner_share+F3*in_hlth_family_ticket*in_hlth_family_renew_comm*in_ins_partner_share*(in_hlth_family_renew^1*SUMIFS(AI2:AI61,B2:B61,B3-12)+in_hlth_family_renew^2*SUMIFS(AI2:AI61,B2:B61,B3-24)+in_hlth_family_renew^3*SUMIFS(AI2:AI61,B2:B61,B3-36)+in_hlth_family_renew^4*SUMIFS(AI2:AI61,B2:B61,B3-48)) | AK3: =AK2*(1-IF(B2>=in_marketplace_from,d_hz_life_term*G2,0)) | AL3: =AK3*IF(B3>=in_marketplace_from,d_hz_life_term*G3,0) | AM3: =F3*AL3*in_life_term_ticket*in_life_term_comm*in_ins_partner_share+F3*in_life_term_ticket*in_life_term_renew_comm*in_ins_partner_share*(in_life_term_renew^1*SUMIFS(AL2:AL61,B2:B61,B3-12)+in_life_term_renew^2*SUMIFS(AL2:AL61,B2:B61,B3-24)+in_life_term_renew^3*SUMIFS(AL2:AL61,B2:B61,B3-36)+in_life_term_renew^4*SUMIFS(AL2:AL61,B2:B61,B3-48)) | AN3: =AN2*(1-IF(B2>=in_marketplace_from,d_hz_accident*G2,0)) | AO3: =AN3*IF(B3>=in_marketplace_from,d_hz_accident*G3,0) | AP3: =F3*AO3*in_accident_ticket*in_accident_comm*in_ins_partner_share+F3*in_accident_ticket*in_accident_renew_comm*in_ins_partner_share*(in_accident_renew^1*SUMIFS(AO2:AO61,B2:B61,B3-12)+in_accident_renew^2*SUMIFS(AO2:AO61,B2:B61,B3-24)+in_accident_renew^3*SUMIFS(AO2:AO61,B2:B61,B3-36)+in_accident_renew^4*SUMIFS(AO2:AO61,B2:B61,B3-48)) | AQ3: =AQ2*(1-IF(B2>=in_marketplace_from,d_hz_two_wheeler*G2,0)) | AR3: =AQ3*IF(B3>=in_marketplace_from,d_hz_two_wheeler*G3,0) | AS3: =F3*AR3*in_two_wheeler_ticket*in_two_wheeler_comm*in_ins_partner_share+F3*in_two_wheeler_ticket*in_two_wheeler_comm*in_ins_partner_share*(in_two_wheeler_renew^1*SUMIFS(AR2:AR61,B2:B61,B3-12)+in_two_wheeler_renew^2*SUMIFS(AR2:AR61,B2:B61,B3-24)+in_two_wheeler_renew^3*SUMIFS(AR2:AR61,B2:B61,B3-36)+in_two_wheeler_renew^4*SUMIFS(AR2:AR61,B2:B61,B3-48)) | AT3: =AT2*(1-IF(B2>=in_marketplace_from,d_hz_device*G2,0)) | AU3: =F3*AT3*IF(B3>=in_marketplace_from,d_hz_device*G3,0)*in_device_ticket*in_device_comm*in_ins_partner_share | AV3: =AV2*(1-IF(B2>=in_marketplace_from,d_hz_shop*G2,0)) | AW3: =AV3*IF(B3>=in_marketplace_from,d_hz_shop*G3,0) | AX3: =F3*AW3*in_shop_ticket*in_shop_comm*in_ins_partner_share+F3*in_shop_ticket*in_shop_renew_comm*in_ins_partner_share*(in_shop_renew^1*SUMIFS(AW2:AW61,B2:B61,B3-12)+in_shop_renew^2*SUMIFS(AW2:AW61,B2:B61,B3-24)+in_shop_renew^3*SUMIFS(AW2:AW61,B2:B61,B3-36)+in_shop_renew^4*SUMIFS(AW2:AW61,B2:B61,B3-48)) | AY3: =AY2*(1-IF(B2>=in_marketplace_from,d_hz_sip*G2,0)) | AZ3: =AZ2*d_rho_sip+AY3*IF(B3>=in_marketplace_from,d_hz_sip*G3,0) | BA3: =d_rho_sip*(BA2+AZ2) | BB3: =F3*in_sip_ticket*(BA3+0.5*AZ3)*in_sip_comm/12 | BC3: =BC2*(1-IF(B2>=in_marketplace_from,d_hz_choti*G2,0)) | BD3: =BC3*IF(B3>=in_marketplace_from,d_hz_choti*G3,0) | BE3: =F3*SUMIFS(BD2:BD61,B2:B61,B3-in_choti_months)*in_choti_renew*in_choti_ticket | BF3: =BF2*(1-IF(B2>=in_marketplace_from,d_hz_nps*G2,0)) | BG3: =F3*BF3*IF(B3>=in_marketplace_from,d_hz_nps*G3,0)*in_nps_ticket*in_nps_comm | BH3: =BH2*(1-IF(B2>=in_marketplace_from,d_hz_gold*G2,0)) | BI3: =BI2*d_rho_gold+BH3*IF(B3>=in_marketplace_from,d_hz_gold*G3,0) | BJ3: =F3*BI3*in_gold_ticket*in_gold_comm | BK3: =BK2*(1-IF(B2>=in_marketplace_from,d_hz_fd*G2,0)) | BL3: =F3*BK3*IF(B3>=in_marketplace_from,d_hz_fd*G3,0)*in_fd_ticket*in_fd_comm | BM3: =BM2*(1-IF(B2>=in_marketplace_from,d_hz_recharge*G2,0)) | BN3: =BN2*d_rho_recharge+BM3*IF(B3>=in_marketplace_from,d_hz_recharge*G3,0) | BO3: =F3*BN3*in_recharge_ticket*in_recharge_comm/12 | BP3: =BP2*(1-IF(B2>=in_marketplace_from,d_hz_bills*G2,0)) | BQ3: =BQ2*d_rho_bills+BP3*IF(B3>=in_marketplace_from,d_hz_bills*G3,0) | BR3: =F3*BQ3*in_bills_ticket*in_bills_comm/12 | BS3: =BS2*(1-IF(B2>=in_marketplace_from,d_hz_loan_gold*G2,0)) | BT3: =F3*BS3*IF(B3>=in_marketplace_from,d_hz_loan_gold*G3,0)*in_loan_gold_ticket*in_loan_gold_comm | BU3: =BU2*(1-IF(B2>=in_marketplace_from,d_hz_loan_cd*G2,0)) | BV3: =F3*BU3*IF(B3>=in_marketplace_from,d_hz_loan_cd*G3,0)*in_loan_cd_ticket*in_loan_cd_comm | BW3: =BW2*(1-IF(B2>=in_marketplace_from,d_hz_loan_vehicle*G2,0)) | BX3: =F3*BW3*IF(B3>=in_marketplace_from,d_hz_loan_vehicle*G3,0)*in_loan_vehicle_ticket*in_loan_vehicle_comm | BY3: =BY2*(1-IF(B2>=in_marketplace_from,d_hz_loan_home*G2,0)*BZ2) | BZ3: =MIN(in_approval_cap,in_loan_home_approval*INDEX('Age profile'!$O$2:$O$61,B3)*(1+in_approval_growth)^(D3-1)) | CA3: =F3*BY3*IF(B3>=in_marketplace_from,d_hz_loan_home*G3,0)*BZ3*in_loan_home_ticket*in_loan_home_comm | CB3: =CB2*(1-IF(B2>=in_marketplace_from,d_hz_loan_lap*G2,0)*CC2) | CC3: =MIN(in_approval_cap,in_loan_lap_approval*INDEX('Age profile'!$O$2:$O$61,B3)*(1+in_approval_growth)^(D3-1)) | CD3: =F3*CB3*IF(B3>=in_marketplace_from,d_hz_loan_lap*G3,0)*CC3*in_loan_lap_ticket*in_loan_lap_comm | CE3: =AA3+AB3+AC3+AD3+AG3+AJ3+AM3+AP3+AS3+AU3+AX3+BB3+BE3+BG3+BJ3+BL3+BO3+BR3+BT3+BV3+BX3+CA3+CD3
A4: 1 | B4: 3 | C4: =A4+B4-1 | D4: =INT((C4-1)/12)+1 | E4: =INDEX(Monthly!$B$2:$B$61,A4) | F4: =E4*INDEX('Age profile'!$B$2:$B$61,B4) | G4: =MIN(in_takeup_cap,INDEX('Age profile'!$N$2:$N$61,B4)*(1+in_takeup_growth)^(D4-1)) | H4: =MIN(in_approval_cap,in_approved_first*INDEX('Age profile'!$O$2:$O$61,B4)*(1+in_approval_growth)^(D4-1)) | I4: =G4*MIN(in_takeup_cap,INDEX('Age profile'!$O$2:$O$61,B4)*(1+in_approval_growth)^(D4-1)) | J4: =(J3-L3)*F4/F3 | K4: =(K3-M3)*F4/F3+SUMIFS(O2:O3,B2:B3,B4-1-d_T)*F4 | L4: =IF(B4>=in_marketplace_from,J4*d_hz*G4*in_eligible*H4,0) | M4: =IF(B4>=in_marketplace_from,K4*d_hz*G4*in_eligible*in_approved_repeat,0) | N4: =L4+M4 | O4: =N4/F4 | P4: =F4-J4-K4 | Q4: =IF(B4>=in_marketplace_from,(J4+K4)*d_hz*G4,0) | R4: =SUMIFS(N2:N61,B2:B61,">="&(B4-d_T),B2:B61,"<="&(B4-1)) | S4: =(1-d_u)*S3+IF(d_T>in_topup_lag,SUMIFS(O2:O61,B2:B61,B4-in_topup_lag)-d_udrop*SUMIFS(O2:O61,B2:B61,B4-d_T),0) | T4: =F4*d_u*S4 | U4: =L4*in_ticket+M4*d_rep_ticket | V4: =U4+T4*d_topup_amt | W4: =N4+T4*d_topup_ratio | X4: =SUMIFS(W2:W61,B2:B61,B4-in_dpd_lag)*d_cured | Y4: =SUMIFS(W2:W61,B2:B61,B4-in_rec_lag)*d_recd | Z4: =IF(AND(B4>=in_marketplace_from,B4<in_marketplace_from+in_card_months),in_card_share/in_card_months*F4*I4,IF(AND(B4>=in_marketplace_from+in_card_months,B4<in_marketplace_from+2*in_card_months),in_card_share*d_card_rem/in_card_months*F4*MIN(in_takeup_cap,(1+in_takeup_growth)^(D4-1))*MIN(in_takeup_cap,(1+in_approval_growth)^(D4-1)),0)) | AA4: =V4*in_fee*(1-in_taken_back) | AB4: =SUMIFS(W2:W61,B2:B61,B4-in_dpd_lag)*d_dpd | AC4: =SUMIFS(W2:W61,B2:B61,B4-in_rec_lag)*d_rec | AD4: =Z4*in_card_fee | AE4: =AE3*(1-IF(B3>=in_marketplace_from,d_hz_hlth_small*G3,0)) | AF4: =AE4*IF(B4>=in_marketplace_from,d_hz_hlth_small*G4,0) | AG4: =F4*AF4*in_hlth_small_ticket*in_hlth_small_comm*in_ins_partner_share+F4*in_hlth_small_ticket*in_hlth_small_renew_comm*in_ins_partner_share*(in_hlth_small_renew^1*SUMIFS(AF2:AF61,B2:B61,B4-12)+in_hlth_small_renew^2*SUMIFS(AF2:AF61,B2:B61,B4-24)+in_hlth_small_renew^3*SUMIFS(AF2:AF61,B2:B61,B4-36)+in_hlth_small_renew^4*SUMIFS(AF2:AF61,B2:B61,B4-48)) | AH4: =AH3*(1-IF(B3>=in_marketplace_from,d_hz_hlth_family*G3,0)) | AI4: =AH4*IF(B4>=in_marketplace_from,d_hz_hlth_family*G4,0) | AJ4: =F4*AI4*in_hlth_family_ticket*in_hlth_family_comm*in_ins_partner_share+F4*in_hlth_family_ticket*in_hlth_family_renew_comm*in_ins_partner_share*(in_hlth_family_renew^1*SUMIFS(AI2:AI61,B2:B61,B4-12)+in_hlth_family_renew^2*SUMIFS(AI2:AI61,B2:B61,B4-24)+in_hlth_family_renew^3*SUMIFS(AI2:AI61,B2:B61,B4-36)+in_hlth_family_renew^4*SUMIFS(AI2:AI61,B2:B61,B4-48)) | AK4: =AK3*(1-IF(B3>=in_marketplace_from,d_hz_life_term*G3,0)) | AL4: =AK4*IF(B4>=in_marketplace_from,d_hz_life_term*G4,0) | AM4: =F4*AL4*in_life_term_ticket*in_life_term_comm*in_ins_partner_share+F4*in_life_term_ticket*in_life_term_renew_comm*in_ins_partner_share*(in_life_term_renew^1*SUMIFS(AL2:AL61,B2:B61,B4-12)+in_life_term_renew^2*SUMIFS(AL2:AL61,B2:B61,B4-24)+in_life_term_renew^3*SUMIFS(AL2:AL61,B2:B61,B4-36)+in_life_term_renew^4*SUMIFS(AL2:AL61,B2:B61,B4-48)) | AN4: =AN3*(1-IF(B3>=in_marketplace_from,d_hz_accident*G3,0)) | AO4: =AN4*IF(B4>=in_marketplace_from,d_hz_accident*G4,0) | AP4: =F4*AO4*in_accident_ticket*in_accident_comm*in_ins_partner_share+F4*in_accident_ticket*in_accident_renew_comm*in_ins_partner_share*(in_accident_renew^1*SUMIFS(AO2:AO61,B2:B61,B4-12)+in_accident_renew^2*SUMIFS(AO2:AO61,B2:B61,B4-24)+in_accident_renew^3*SUMIFS(AO2:AO61,B2:B61,B4-36)+in_accident_renew^4*SUMIFS(AO2:AO61,B2:B61,B4-48)) | AQ4: =AQ3*(1-IF(B3>=in_marketplace_from,d_hz_two_wheeler*G3,0)) | AR4: =AQ4*IF(B4>=in_marketplace_from,d_hz_two_wheeler*G4,0) | AS4: =F4*AR4*in_two_wheeler_ticket*in_two_wheeler_comm*in_ins_partner_share+F4*in_two_wheeler_ticket*in_two_wheeler_comm*in_ins_partner_share*(in_two_wheeler_renew^1*SUMIFS(AR2:AR61,B2:B61,B4-12)+in_two_wheeler_renew^2*SUMIFS(AR2:AR61,B2:B61,B4-24)+in_two_wheeler_renew^3*SUMIFS(AR2:AR61,B2:B61,B4-36)+in_two_wheeler_renew^4*SUMIFS(AR2:AR61,B2:B61,B4-48)) | AT4: =AT3*(1-IF(B3>=in_marketplace_from,d_hz_device*G3,0)) | AU4: =F4*AT4*IF(B4>=in_marketplace_from,d_hz_device*G4,0)*in_device_ticket*in_device_comm*in_ins_partner_share | AV4: =AV3*(1-IF(B3>=in_marketplace_from,d_hz_shop*G3,0)) | AW4: =AV4*IF(B4>=in_marketplace_from,d_hz_shop*G4,0) | AX4: =F4*AW4*in_shop_ticket*in_shop_comm*in_ins_partner_share+F4*in_shop_ticket*in_shop_renew_comm*in_ins_partner_share*(in_shop_renew^1*SUMIFS(AW2:AW61,B2:B61,B4-12)+in_shop_renew^2*SUMIFS(AW2:AW61,B2:B61,B4-24)+in_shop_renew^3*SUMIFS(AW2:AW61,B2:B61,B4-36)+in_shop_renew^4*SUMIFS(AW2:AW61,B2:B61,B4-48)) | AY4: =AY3*(1-IF(B3>=in_marketplace_from,d_hz_sip*G3,0)) | AZ4: =AZ3*d_rho_sip+AY4*IF(B4>=in_marketplace_from,d_hz_sip*G4,0) | BA4: =d_rho_sip*(BA3+AZ3) | BB4: =F4*in_sip_ticket*(BA4+0.5*AZ4)*in_sip_comm/12 | BC4: =BC3*(1-IF(B3>=in_marketplace_from,d_hz_choti*G3,0)) | BD4: =BC4*IF(B4>=in_marketplace_from,d_hz_choti*G4,0) | BE4: =F4*SUMIFS(BD2:BD61,B2:B61,B4-in_choti_months)*in_choti_renew*in_choti_ticket | BF4: =BF3*(1-IF(B3>=in_marketplace_from,d_hz_nps*G3,0)) | BG4: =F4*BF4*IF(B4>=in_marketplace_from,d_hz_nps*G4,0)*in_nps_ticket*in_nps_comm | BH4: =BH3*(1-IF(B3>=in_marketplace_from,d_hz_gold*G3,0)) | BI4: =BI3*d_rho_gold+BH4*IF(B4>=in_marketplace_from,d_hz_gold*G4,0) | BJ4: =F4*BI4*in_gold_ticket*in_gold_comm | BK4: =BK3*(1-IF(B3>=in_marketplace_from,d_hz_fd*G3,0)) | BL4: =F4*BK4*IF(B4>=in_marketplace_from,d_hz_fd*G4,0)*in_fd_ticket*in_fd_comm | BM4: =BM3*(1-IF(B3>=in_marketplace_from,d_hz_recharge*G3,0)) | BN4: =BN3*d_rho_recharge+BM4*IF(B4>=in_marketplace_from,d_hz_recharge*G4,0) | BO4: =F4*BN4*in_recharge_ticket*in_recharge_comm/12 | BP4: =BP3*(1-IF(B3>=in_marketplace_from,d_hz_bills*G3,0)) | BQ4: =BQ3*d_rho_bills+BP4*IF(B4>=in_marketplace_from,d_hz_bills*G4,0) | BR4: =F4*BQ4*in_bills_ticket*in_bills_comm/12 | BS4: =BS3*(1-IF(B3>=in_marketplace_from,d_hz_loan_gold*G3,0)) | BT4: =F4*BS4*IF(B4>=in_marketplace_from,d_hz_loan_gold*G4,0)*in_loan_gold_ticket*in_loan_gold_comm | BU4: =BU3*(1-IF(B3>=in_marketplace_from,d_hz_loan_cd*G3,0)) | BV4: =F4*BU4*IF(B4>=in_marketplace_from,d_hz_loan_cd*G4,0)*in_loan_cd_ticket*in_loan_cd_comm | BW4: =BW3*(1-IF(B3>=in_marketplace_from,d_hz_loan_vehicle*G3,0)) | BX4: =F4*BW4*IF(B4>=in_marketplace_from,d_hz_loan_vehicle*G4,0)*in_loan_vehicle_ticket*in_loan_vehicle_comm | BY4: =BY3*(1-IF(B3>=in_marketplace_from,d_hz_loan_home*G3,0)*BZ3) | BZ4: =MIN(in_approval_cap,in_loan_home_approval*INDEX('Age profile'!$O$2:$O$61,B4)*(1+in_approval_growth)^(D4-1)) | CA4: =F4*BY4*IF(B4>=in_marketplace_from,d_hz_loan_home*G4,0)*BZ4*in_loan_home_ticket*in_loan_home_comm | CB4: =CB3*(1-IF(B3>=in_marketplace_from,d_hz_loan_lap*G3,0)*CC3) | CC4: =MIN(in_approval_cap,in_loan_lap_approval*INDEX('Age profile'!$O$2:$O$61,B4)*(1+in_approval_growth)^(D4-1)) | CD4: =F4*CB4*IF(B4>=in_marketplace_from,d_hz_loan_lap*G4,0)*CC4*in_loan_lap_ticket*in_loan_lap_comm | CE4: =AA4+AB4+AC4+AD4+AG4+AJ4+AM4+AP4+AS4+AU4+AX4+BB4+BE4+BG4+BJ4+BL4+BO4+BR4+BT4+BV4+BX4+CA4+CD4
A5: 1 | B5: 4 | C5: =A5+B5-1 | D5: =INT((C5-1)/12)+1 | E5: =INDEX(Monthly!$B$2:$B$61,A5) | F5: =E5*INDEX('Age profile'!$B$2:$B$61,B5) | G5: =MIN(in_takeup_cap,INDEX('Age profile'!$N$2:$N$61,B5)*(1+in_takeup_growth)^(D5-1)) | H5: =MIN(in_approval_cap,in_approved_first*INDEX('Age profile'!$O$2:$O$61,B5)*(1+in_approval_growth)^(D5-1)) | I5: =G5*MIN(in_takeup_cap,INDEX('Age profile'!$O$2:$O$61,B5)*(1+in_approval_growth)^(D5-1)) | J5: =(J4-L4)*F5/F4 | K5: =(K4-M4)*F5/F4+SUMIFS(O2:O4,B2:B4,B5-1-d_T)*F5 | L5: =IF(B5>=in_marketplace_from,J5*d_hz*G5*in_eligible*H5,0) | M5: =IF(B5>=in_marketplace_from,K5*d_hz*G5*in_eligible*in_approved_repeat,0) | N5: =L5+M5 | O5: =N5/F5 | P5: =F5-J5-K5 | Q5: =IF(B5>=in_marketplace_from,(J5+K5)*d_hz*G5,0) | R5: =SUMIFS(N2:N61,B2:B61,">="&(B5-d_T),B2:B61,"<="&(B5-1)) | S5: =(1-d_u)*S4+IF(d_T>in_topup_lag,SUMIFS(O2:O61,B2:B61,B5-in_topup_lag)-d_udrop*SUMIFS(O2:O61,B2:B61,B5-d_T),0) | T5: =F5*d_u*S5 | U5: =L5*in_ticket+M5*d_rep_ticket | V5: =U5+T5*d_topup_amt | W5: =N5+T5*d_topup_ratio | X5: =SUMIFS(W2:W61,B2:B61,B5-in_dpd_lag)*d_cured | Y5: =SUMIFS(W2:W61,B2:B61,B5-in_rec_lag)*d_recd | Z5: =IF(AND(B5>=in_marketplace_from,B5<in_marketplace_from+in_card_months),in_card_share/in_card_months*F5*I5,IF(AND(B5>=in_marketplace_from+in_card_months,B5<in_marketplace_from+2*in_card_months),in_card_share*d_card_rem/in_card_months*F5*MIN(in_takeup_cap,(1+in_takeup_growth)^(D5-1))*MIN(in_takeup_cap,(1+in_approval_growth)^(D5-1)),0)) | AA5: =V5*in_fee*(1-in_taken_back) | AB5: =SUMIFS(W2:W61,B2:B61,B5-in_dpd_lag)*d_dpd | AC5: =SUMIFS(W2:W61,B2:B61,B5-in_rec_lag)*d_rec | AD5: =Z5*in_card_fee | AE5: =AE4*(1-IF(B4>=in_marketplace_from,d_hz_hlth_small*G4,0)) | AF5: =AE5*IF(B5>=in_marketplace_from,d_hz_hlth_small*G5,0) | AG5: =F5*AF5*in_hlth_small_ticket*in_hlth_small_comm*in_ins_partner_share+F5*in_hlth_small_ticket*in_hlth_small_renew_comm*in_ins_partner_share*(in_hlth_small_renew^1*SUMIFS(AF2:AF61,B2:B61,B5-12)+in_hlth_small_renew^2*SUMIFS(AF2:AF61,B2:B61,B5-24)+in_hlth_small_renew^3*SUMIFS(AF2:AF61,B2:B61,B5-36)+in_hlth_small_renew^4*SUMIFS(AF2:AF61,B2:B61,B5-48)) | AH5: =AH4*(1-IF(B4>=in_marketplace_from,d_hz_hlth_family*G4,0)) | AI5: =AH5*IF(B5>=in_marketplace_from,d_hz_hlth_family*G5,0) | AJ5: =F5*AI5*in_hlth_family_ticket*in_hlth_family_comm*in_ins_partner_share+F5*in_hlth_family_ticket*in_hlth_family_renew_comm*in_ins_partner_share*(in_hlth_family_renew^1*SUMIFS(AI2:AI61,B2:B61,B5-12)+in_hlth_family_renew^2*SUMIFS(AI2:AI61,B2:B61,B5-24)+in_hlth_family_renew^3*SUMIFS(AI2:AI61,B2:B61,B5-36)+in_hlth_family_renew^4*SUMIFS(AI2:AI61,B2:B61,B5-48)) | AK5: =AK4*(1-IF(B4>=in_marketplace_from,d_hz_life_term*G4,0)) | AL5: =AK5*IF(B5>=in_marketplace_from,d_hz_life_term*G5,0) | AM5: =F5*AL5*in_life_term_ticket*in_life_term_comm*in_ins_partner_share+F5*in_life_term_ticket*in_life_term_renew_comm*in_ins_partner_share*(in_life_term_renew^1*SUMIFS(AL2:AL61,B2:B61,B5-12)+in_life_term_renew^2*SUMIFS(AL2:AL61,B2:B61,B5-24)+in_life_term_renew^3*SUMIFS(AL2:AL61,B2:B61,B5-36)+in_life_term_renew^4*SUMIFS(AL2:AL61,B2:B61,B5-48)) | AN5: =AN4*(1-IF(B4>=in_marketplace_from,d_hz_accident*G4,0)) | AO5: =AN5*IF(B5>=in_marketplace_from,d_hz_accident*G5,0) | AP5: =F5*AO5*in_accident_ticket*in_accident_comm*in_ins_partner_share+F5*in_accident_ticket*in_accident_renew_comm*in_ins_partner_share*(in_accident_renew^1*SUMIFS(AO2:AO61,B2:B61,B5-12)+in_accident_renew^2*SUMIFS(AO2:AO61,B2:B61,B5-24)+in_accident_renew^3*SUMIFS(AO2:AO61,B2:B61,B5-36)+in_accident_renew^4*SUMIFS(AO2:AO61,B2:B61,B5-48)) | AQ5: =AQ4*(1-IF(B4>=in_marketplace_from,d_hz_two_wheeler*G4,0)) | AR5: =AQ5*IF(B5>=in_marketplace_from,d_hz_two_wheeler*G5,0) | AS5: =F5*AR5*in_two_wheeler_ticket*in_two_wheeler_comm*in_ins_partner_share+F5*in_two_wheeler_ticket*in_two_wheeler_comm*in_ins_partner_share*(in_two_wheeler_renew^1*SUMIFS(AR2:AR61,B2:B61,B5-12)+in_two_wheeler_renew^2*SUMIFS(AR2:AR61,B2:B61,B5-24)+in_two_wheeler_renew^3*SUMIFS(AR2:AR61,B2:B61,B5-36)+in_two_wheeler_renew^4*SUMIFS(AR2:AR61,B2:B61,B5-48)) | AT5: =AT4*(1-IF(B4>=in_marketplace_from,d_hz_device*G4,0)) | AU5: =F5*AT5*IF(B5>=in_marketplace_from,d_hz_device*G5,0)*in_device_ticket*in_device_comm*in_ins_partner_share | AV5: =AV4*(1-IF(B4>=in_marketplace_from,d_hz_shop*G4,0)) | AW5: =AV5*IF(B5>=in_marketplace_from,d_hz_shop*G5,0) | AX5: =F5*AW5*in_shop_ticket*in_shop_comm*in_ins_partner_share+F5*in_shop_ticket*in_shop_renew_comm*in_ins_partner_share*(in_shop_renew^1*SUMIFS(AW2:AW61,B2:B61,B5-12)+in_shop_renew^2*SUMIFS(AW2:AW61,B2:B61,B5-24)+in_shop_renew^3*SUMIFS(AW2:AW61,B2:B61,B5-36)+in_shop_renew^4*SUMIFS(AW2:AW61,B2:B61,B5-48)) | AY5: =AY4*(1-IF(B4>=in_marketplace_from,d_hz_sip*G4,0)) | AZ5: =AZ4*d_rho_sip+AY5*IF(B5>=in_marketplace_from,d_hz_sip*G5,0) | BA5: =d_rho_sip*(BA4+AZ4) | BB5: =F5*in_sip_ticket*(BA5+0.5*AZ5)*in_sip_comm/12 | BC5: =BC4*(1-IF(B4>=in_marketplace_from,d_hz_choti*G4,0)) | BD5: =BC5*IF(B5>=in_marketplace_from,d_hz_choti*G5,0) | BE5: =F5*SUMIFS(BD2:BD61,B2:B61,B5-in_choti_months)*in_choti_renew*in_choti_ticket | BF5: =BF4*(1-IF(B4>=in_marketplace_from,d_hz_nps*G4,0)) | BG5: =F5*BF5*IF(B5>=in_marketplace_from,d_hz_nps*G5,0)*in_nps_ticket*in_nps_comm | BH5: =BH4*(1-IF(B4>=in_marketplace_from,d_hz_gold*G4,0)) | BI5: =BI4*d_rho_gold+BH5*IF(B5>=in_marketplace_from,d_hz_gold*G5,0) | BJ5: =F5*BI5*in_gold_ticket*in_gold_comm | BK5: =BK4*(1-IF(B4>=in_marketplace_from,d_hz_fd*G4,0)) | BL5: =F5*BK5*IF(B5>=in_marketplace_from,d_hz_fd*G5,0)*in_fd_ticket*in_fd_comm | BM5: =BM4*(1-IF(B4>=in_marketplace_from,d_hz_recharge*G4,0)) | BN5: =BN4*d_rho_recharge+BM5*IF(B5>=in_marketplace_from,d_hz_recharge*G5,0) | BO5: =F5*BN5*in_recharge_ticket*in_recharge_comm/12 | BP5: =BP4*(1-IF(B4>=in_marketplace_from,d_hz_bills*G4,0)) | BQ5: =BQ4*d_rho_bills+BP5*IF(B5>=in_marketplace_from,d_hz_bills*G5,0) | BR5: =F5*BQ5*in_bills_ticket*in_bills_comm/12 | BS5: =BS4*(1-IF(B4>=in_marketplace_from,d_hz_loan_gold*G4,0)) | BT5: =F5*BS5*IF(B5>=in_marketplace_from,d_hz_loan_gold*G5,0)*in_loan_gold_ticket*in_loan_gold_comm | BU5: =BU4*(1-IF(B4>=in_marketplace_from,d_hz_loan_cd*G4,0)) | BV5: =F5*BU5*IF(B5>=in_marketplace_from,d_hz_loan_cd*G5,0)*in_loan_cd_ticket*in_loan_cd_comm | BW5: =BW4*(1-IF(B4>=in_marketplace_from,d_hz_loan_vehicle*G4,0)) | BX5: =F5*BW5*IF(B5>=in_marketplace_from,d_hz_loan_vehicle*G5,0)*in_loan_vehicle_ticket*in_loan_vehicle_comm | BY5: =BY4*(1-IF(B4>=in_marketplace_from,d_hz_loan_home*G4,0)*BZ4) | BZ5: =MIN(in_approval_cap,in_loan_home_approval*INDEX('Age profile'!$O$2:$O$61,B5)*(1+in_approval_growth)^(D5-1)) | CA5: =F5*BY5*IF(B5>=in_marketplace_from,d_hz_loan_home*G5,0)*BZ5*in_loan_home_ticket*in_loan_home_comm | CB5: =CB4*(1-IF(B4>=in_marketplace_from,d_hz_loan_lap*G4,0)*CC4) | CC5: =MIN(in_approval_cap,in_loan_lap_approval*INDEX('Age profile'!$O$2:$O$61,B5)*(1+in_approval_growth)^(D5-1)) | CD5: =F5*CB5*IF(B5>=in_marketplace_from,d_hz_loan_lap*G5,0)*CC5*in_loan_lap_ticket*in_loan_lap_comm | CE5: =AA5+AB5+AC5+AD5+AG5+AJ5+AM5+AP5+AS5+AU5+AX5+BB5+BE5+BG5+BJ5+BL5+BO5+BR5+BT5+BV5+BX5+CA5+CD5
